*** Starting uWSGI 2.0.18 (64bit) on [Sun May 26 16:35:10 2019] ***
compiled with version: 7.3.0 on 26 May 2019 07:39:13
os: Linux-4.15.0-36-generic #39-Ubuntu SMP Mon Sep 24 16:19:09 UTC 2018
nodename: VIP
machine: x86_64
clock source: unix
pcre jit disabled
detected number of CPU cores: 1
current working directory: /home/pyvip/project/mysite/deploy
writing pidfile to uwsgi.pid
detected binary path: /home/pyvip/.virtualenvs/mysites/bin/uwsgi
chdir() to /home/pyvip/project/mysite
your processes number limit is 3705
your memory page size is 4096 bytes
detected max file descriptor number: 1024
lock engine: pthread robust mutexes
thunder lock: disabled (you can enable it with --thunder-lock)
probably another instance of uWSGI is running on the same address (10.0.2.15:8000).
bind(): Address already in use [core/socket.c line 769]
invalid request block size: 21573 (max 4096)...skip
invalid request block size: 21573 (max 4096)...skip
invalid request block size: 21573 (max 4096)...skip
invalid request block size: 21573 (max 4096)...skip
invalid request block size: 21573 (max 4096)...skip
invalid request block size: 21573 (max 4096)...skip
invalid request block size: 21573 (max 4096)...skip
invalid request block size: 21573 (max 4096)...skip
invalid request block size: 21573 (max 4096)...skip
invalid request block size: 21573 (max 4096)...skip
invalid request block size: 21573 (max 4096)...skip
invalid request block size: 21573 (max 4096)...skip
invalid request block size: 21573 (max 4096)...skip
invalid request block size: 21573 (max 4096)...skip
invalid request block size: 21573 (max 4096)...skip
invalid request block size: 21573 (max 4096)...skip
invalid request block size: 21573 (max 4096)...skip
invalid request block size: 21573 (max 4096)...skip
invalid request block size: 21573 (max 4096)...skip
invalid request block size: 21573 (max 4096)...skip
invalid request block size: 21573 (max 4096)...skip
invalid request block size: 21573 (max 4096)...skip
invalid request block size: 21573 (max 4096)...skip
invalid request block size: 21573 (max 4096)...skip
*** Starting uWSGI 2.0.18 (64bit) on [Sun May 26 17:52:12 2019] ***
compiled with version: 7.3.0 on 26 May 2019 07:39:13
os: Linux-4.15.0-36-generic #39-Ubuntu SMP Mon Sep 24 16:19:09 UTC 2018
nodename: VIP
machine: x86_64
clock source: unix
pcre jit disabled
detected number of CPU cores: 1
current working directory: /home/pyvip/project/mysite/deploy
writing pidfile to uwsgi.pid
detected binary path: /home/pyvip/.virtualenvs/mysites/bin/uwsgi
chdir() to /home/pyvip/project/mysite
your processes number limit is 3705
your memory page size is 4096 bytes
detected max file descriptor number: 1024
lock engine: pthread robust mutexes
thunder lock: disabled (you can enable it with --thunder-lock)
probably another instance of uWSGI is running on the same address (10.0.2.15:8000).
bind(): Address already in use [core/socket.c line 769]
invalid request block size: 21573 (max 4096)...skip
invalid request block size: 21573 (max 4096)...skip
invalid request block size: 21573 (max 4096)...skip
invalid request block size: 21573 (max 4096)...skip
invalid request block size: 21573 (max 4096)...skip
invalid request block size: 21573 (max 4096)...skip
invalid request block size: 21573 (max 4096)...skip
invalid request block size: 21573 (max 4096)...skip
invalid request block size: 21573 (max 4096)...skip
invalid request block size: 21573 (max 4096)...skip
invalid request block size: 21573 (max 4096)...skip
invalid request block size: 21573 (max 4096)...skip
invalid request block size: 21573 (max 4096)...skip
invalid request block size: 21573 (max 4096)...skip
invalid request block size: 21573 (max 4096)...skip
invalid request block size: 21573 (max 4096)...skip
invalid request block size: 21573 (max 4096)...skip
invalid request block size: 21573 (max 4096)...skip
invalid request block size: 21573 (max 4096)...skip
invalid request block size: 21573 (max 4096)...skip
invalid request block size: 21573 (max 4096)...skip
invalid request block size: 21573 (max 4096)...skip
invalid request block size: 21573 (max 4096)...skip
invalid request block size: 21573 (max 4096)...skip
invalid request block size: 21573 (max 4096)...skip
invalid request block size: 21573 (max 4096)...skip
invalid request block size: 21573 (max 4096)...skip
invalid request block size: 21573 (max 4096)...skip
invalid request block size: 21573 (max 4096)...skip
invalid request block size: 21573 (max 4096)...skip
invalid request block size: 21573 (max 4096)...skip
invalid request block size: 21573 (max 4096)...skip
invalid request block size: 21573 (max 4096)...skip
invalid request block size: 21573 (max 4096)...skip
*** Starting uWSGI 2.0.18 (64bit) on [Mon May 27 14:41:26 2019] ***
compiled with version: 7.3.0 on 26 May 2019 07:39:13
os: Linux-4.15.0-36-generic #39-Ubuntu SMP Mon Sep 24 16:19:09 UTC 2018
nodename: VIP
machine: x86_64
clock source: unix
pcre jit disabled
detected number of CPU cores: 1
current working directory: /home/pyvip/project/mysite/deploy
writing pidfile to uwsgi.pid
detected binary path: /home/pyvip/.virtualenvs/mysites/bin/uwsgi
chdir() to /home/pyvip/project/mysite
your processes number limit is 3705
your memory page size is 4096 bytes
detected max file descriptor number: 1024
lock engine: pthread robust mutexes
thunder lock: disabled (you can enable it with --thunder-lock)
uwsgi socket 0 bound to TCP address 10.0.2.15:8000 fd 3
Python version: 3.6.6 (default, Sep 12 2018, 18:26:19)  [GCC 8.0.1 20180414 (experimental) [trunk revision 259383]]
Set PythonHome to /home/pyvip/.virtualenvs/mysites
Python main interpreter initialized at 0x562b70068a60
python threads support enabled
your server socket listen backlog is limited to 100 connections
your mercy for graceful operations on workers is 60 seconds
mapped 145840 bytes (142 KB) for 1 cores
*** Operational MODE: single process ***
WSGI app 0 (mountpoint='') ready in 9 seconds on interpreter 0x562b70068a60 pid: 11361 (default app)
*** uWSGI is running in multiple interpreter mode ***
spawned uWSGI master process (pid: 11361)
spawned uWSGI worker 1 (pid: 11363, cores: 1)
Mon May 27 14:44:21 2019 - uWSGI worker 1 screams: UAAAAAAH my master disconnected: i will kill myself !!!
*** Starting uWSGI 2.0.18 (64bit) on [Mon May 27 14:53:33 2019] ***
compiled with version: 7.3.0 on 26 May 2019 07:39:13
os: Linux-4.15.0-36-generic #39-Ubuntu SMP Mon Sep 24 16:19:09 UTC 2018
nodename: VIP
machine: x86_64
clock source: unix
pcre jit disabled
detected number of CPU cores: 1
current working directory: /home/pyvip/project/mysite/deploy
writing pidfile to uwsgi.pid
detected binary path: /home/pyvip/.virtualenvs/mysites/bin/uwsgi
chdir() to /home/pyvip/project/mysite
your processes number limit is 3705
your memory page size is 4096 bytes
detected max file descriptor number: 1024
lock engine: pthread robust mutexes
thunder lock: disabled (you can enable it with --thunder-lock)
uwsgi socket 0 bound to TCP address 10.0.2.15:8000 fd 3
Python version: 3.6.6 (default, Sep 12 2018, 18:26:19)  [GCC 8.0.1 20180414 (experimental) [trunk revision 259383]]
Set PythonHome to /home/pyvip/.virtualenvs/mysites
Python main interpreter initialized at 0x561ed3195a60
python threads support enabled
your server socket listen backlog is limited to 100 connections
your mercy for graceful operations on workers is 60 seconds
mapped 145840 bytes (142 KB) for 1 cores
*** Operational MODE: single process ***
WSGI app 0 (mountpoint='') ready in 0 seconds on interpreter 0x561ed3195a60 pid: 11389 (default app)
*** uWSGI is running in multiple interpreter mode ***
spawned uWSGI master process (pid: 11389)
spawned uWSGI worker 1 (pid: 11391, cores: 1)
invalid request block size: 21573 (max 4096)...skip
invalid request block size: 21573 (max 4096)...skip
invalid request block size: 21573 (max 4096)...skip
invalid request block size: 21573 (max 4096)...skip
[pid: 11391|app: 0|req: 1/1] 127.0.0.1 () {32 vars in 344 bytes} [Mon May 27 15:28:51 2019] HEAD / => generated 9785 bytes in 4193 msecs (HTTP/1.1 200) 5 headers in 292 bytes (1 switches on core 0)
invalid request block size: 21573 (max 4096)...skip
invalid request block size: 21573 (max 4096)...skip
invalid request block size: 21573 (max 4096)...skip
invalid request block size: 21573 (max 4096)...skip
invalid request block size: 21573 (max 4096)...skip
invalid request block size: 21573 (max 4096)...skip
invalid request block size: 21573 (max 4096)...skip
invalid request block size: 21573 (max 4096)...skip
invalid request block size: 21573 (max 4096)...skip
invalid request block size: 21573 (max 4096)...skip
invalid request block size: 21573 (max 4096)...skip
invalid request block size: 21573 (max 4096)...skip
Mon May 27 23:30:34 2019 - uWSGI worker 1 screams: UAAAAAAH my master disconnected: i will kill myself !!!
*** Starting uWSGI 2.0.18 (64bit) on [Mon May 27 23:31:38 2019] ***
compiled with version: 7.3.0 on 26 May 2019 07:39:13
os: Linux-4.15.0-36-generic #39-Ubuntu SMP Mon Sep 24 16:19:09 UTC 2018
nodename: VIP
machine: x86_64
clock source: unix
pcre jit disabled
detected number of CPU cores: 1
current working directory: /home/pyvip/project/mysite/deploy
writing pidfile to uwsgi.pid
detected binary path: /home/pyvip/.virtualenvs/mysites/bin/uwsgi
chdir() to /home/pyvip/project/mysite
your processes number limit is 3705
your memory page size is 4096 bytes
detected max file descriptor number: 1024
lock engine: pthread robust mutexes
thunder lock: disabled (you can enable it with --thunder-lock)
uwsgi socket 0 bound to TCP address 10.0.2.15:8000 fd 3
Python version: 3.6.6 (default, Sep 12 2018, 18:26:19)  [GCC 8.0.1 20180414 (experimental) [trunk revision 259383]]
Set PythonHome to /home/pyvip/.virtualenvs/mysites
Python main interpreter initialized at 0x563d2a992a60
python threads support enabled
your server socket listen backlog is limited to 100 connections
your mercy for graceful operations on workers is 60 seconds
mapped 145840 bytes (142 KB) for 1 cores
*** Operational MODE: single process ***
WSGI app 0 (mountpoint='') ready in 3 seconds on interpreter 0x563d2a992a60 pid: 14346 (default app)
*** uWSGI is running in multiple interpreter mode ***
spawned uWSGI master process (pid: 14346)
spawned uWSGI worker 1 (pid: 14348, cores: 1)
invalid request block size: 21573 (max 4096)...skip
invalid request block size: 21573 (max 4096)...skip
invalid request block size: 21573 (max 4096)...skip
invalid request block size: 21573 (max 4096)...skip
invalid request block size: 21573 (max 4096)...skip
invalid request block size: 21573 (max 4096)...skip
invalid request block size: 21573 (max 4096)...skip
invalid request block size: 21573 (max 4096)...skip
invalid request block size: 21573 (max 4096)...skip
invalid request block size: 21573 (max 4096)...skip
invalid request block size: 21573 (max 4096)...skip
invalid request block size: 21573 (max 4096)...skip
invalid request block size: 21573 (max 4096)...skip
invalid request block size: 21573 (max 4096)...skip
invalid request block size: 21573 (max 4096)...skip
invalid request block size: 21573 (max 4096)...skip
invalid request block size: 21573 (max 4096)...skip
invalid request block size: 21573 (max 4096)...skip
invalid request block size: 21573 (max 4096)...skip
invalid request block size: 21573 (max 4096)...skip
invalid request block size: 21573 (max 4096)...skip
invalid request block size: 21573 (max 4096)...skip
invalid request block size: 21573 (max 4096)...skip
invalid request block size: 21573 (max 4096)...skip
invalid request block size: 21573 (max 4096)...skip
invalid request block size: 21573 (max 4096)...skip
invalid request block size: 21573 (max 4096)...skip
invalid request block size: 21573 (max 4096)...skip
invalid request block size: 21573 (max 4096)...skip
invalid request block size: 21573 (max 4096)...skip
invalid request block size: 21573 (max 4096)...skip
invalid request block size: 21573 (max 4096)...skip
invalid request block size: 21573 (max 4096)...skip
invalid request block size: 21573 (max 4096)...skip
invalid request block size: 21573 (max 4096)...skip
invalid request block size: 21573 (max 4096)...skip
invalid request block size: 21573 (max 4096)...skip
invalid request block size: 21573 (max 4096)...skip
invalid request block size: 21573 (max 4096)...skip
invalid request block size: 21573 (max 4096)...skip
invalid request block size: 21573 (max 4096)...skip
invalid request block size: 21573 (max 4096)...skip
invalid request block size: 21573 (max 4096)...skip
invalid request block size: 21573 (max 4096)...skip
invalid request block size: 21573 (max 4096)...skip
invalid request block size: 21573 (max 4096)...skip
invalid request block size: 21573 (max 4096)...skip
invalid request block size: 21573 (max 4096)...skip
invalid request block size: 21573 (max 4096)...skip
invalid request block size: 21573 (max 4096)...skip
invalid request block size: 21573 (max 4096)...skip
invalid request block size: 21573 (max 4096)...skip
invalid request block size: 21573 (max 4096)...skip
invalid request block size: 21573 (max 4096)...skip
invalid request block size: 21573 (max 4096)...skip
invalid request block size: 21573 (max 4096)...skip
invalid request block size: 21573 (max 4096)...skip
invalid request block size: 21573 (max 4096)...skip
Traceback (most recent call last):
  File "/home/pyvip/.virtualenvs/mysites/lib/python3.6/site-packages/django/core/handlers/exception.py", line 34, in inner
    response = get_response(request)
  File "/home/pyvip/.virtualenvs/mysites/lib/python3.6/site-packages/django/core/handlers/base.py", line 111, in _get_response
    resolver_match = resolver.resolve(request.path_info)
  File "/home/pyvip/.virtualenvs/mysites/lib/python3.6/site-packages/django/urls/resolvers.py", line 491, in resolve
    for pattern in self.url_patterns:
  File "/home/pyvip/.virtualenvs/mysites/lib/python3.6/site-packages/django/utils/functional.py", line 37, in __get__
    res = instance.__dict__[self.name] = self.func(instance)
  File "/home/pyvip/.virtualenvs/mysites/lib/python3.6/site-packages/django/urls/resolvers.py", line 533, in url_patterns
    patterns = getattr(self.urlconf_module, "urlpatterns", self.urlconf_module)
  File "/home/pyvip/.virtualenvs/mysites/lib/python3.6/site-packages/django/utils/functional.py", line 37, in __get__
    res = instance.__dict__[self.name] = self.func(instance)
  File "/home/pyvip/.virtualenvs/mysites/lib/python3.6/site-packages/django/urls/resolvers.py", line 526, in urlconf_module
    return import_module(self.urlconf_name)
  File "/home/pyvip/.virtualenvs/mysites/lib/python3.6/importlib/__init__.py", line 126, in import_module
    return _bootstrap._gcd_import(name[level:], package, level)
  File "<frozen importlib._bootstrap>", line 994, in _gcd_import
  File "<frozen importlib._bootstrap>", line 971, in _find_and_load
  File "<frozen importlib._bootstrap>", line 955, in _find_and_load_unlocked
  File "<frozen importlib._bootstrap>", line 665, in _load_unlocked
  File "<frozen importlib._bootstrap_external>", line 678, in exec_module
  File "<frozen importlib._bootstrap>", line 219, in _call_with_frames_removed
  File "./mysite/urls.py", line 23, in <module>
    path('', include('news.urls')),
  File "/home/pyvip/.virtualenvs/mysites/lib/python3.6/site-packages/django/urls/conf.py", line 34, in include
    urlconf_module = import_module(urlconf_module)
  File "/home/pyvip/.virtualenvs/mysites/lib/python3.6/importlib/__init__.py", line 126, in import_module
    return _bootstrap._gcd_import(name[level:], package, level)
  File "<frozen importlib._bootstrap>", line 994, in _gcd_import
  File "<frozen importlib._bootstrap>", line 971, in _find_and_load
  File "<frozen importlib._bootstrap>", line 955, in _find_and_load_unlocked
  File "<frozen importlib._bootstrap>", line 665, in _load_unlocked
  File "<frozen importlib._bootstrap_external>", line 678, in exec_module
  File "<frozen importlib._bootstrap>", line 219, in _call_with_frames_removed
  File "/home/pyvip/project/mysite/apps/news/urls.py", line 2, in <module>
    from news import views
  File "/home/pyvip/project/mysite/apps/news/views.py", line 31, in <module>
    @method_decorator(cache_page(timeout=120, cache='page_cache'), name='dispatch')
  File "/home/pyvip/.virtualenvs/mysites/lib/python3.6/site-packages/django/views/decorators/cache.py", line 23, in cache_page
    cache_timeout=timeout, cache_alias=cache, key_prefix=key_prefix
  File "/home/pyvip/.virtualenvs/mysites/lib/python3.6/site-packages/django/utils/decorators.py", line 128, in _make_decorator
    middleware = middleware_class(*m_args, **m_kwargs)
  File "/home/pyvip/.virtualenvs/mysites/lib/python3.6/site-packages/django/middleware/cache.py", line 189, in __init__
    self.cache = caches[self.cache_alias]
  File "/home/pyvip/.virtualenvs/mysites/lib/python3.6/site-packages/django/core/cache/__init__.py", line 76, in __getitem__
    "Could not find config for '%s' in settings.CACHES" % alias
django.core.cache.backends.base.InvalidCacheBackendError: Could not find config for 'page_cache' in settings.CACHES

During handling of the above exception, another exception occurred:

Traceback (most recent call last):
  File "/home/pyvip/.virtualenvs/mysites/lib/python3.6/site-packages/django/core/handlers/exception.py", line 34, in inner
    response = get_response(request)
  File "/home/pyvip/.virtualenvs/mysites/lib/python3.6/site-packages/django/utils/deprecation.py", line 91, in __call__
    response = response or self.get_response(request)
  File "/home/pyvip/.virtualenvs/mysites/lib/python3.6/site-packages/django/core/handlers/exception.py", line 36, in inner
    response = response_for_exception(request, exc)
  File "/home/pyvip/.virtualenvs/mysites/lib/python3.6/site-packages/django/core/handlers/exception.py", line 90, in response_for_exception
    response = handle_uncaught_exception(request, get_resolver(get_urlconf()), sys.exc_info())
  File "/home/pyvip/.virtualenvs/mysites/lib/python3.6/site-packages/django/core/handlers/exception.py", line 128, in handle_uncaught_exception
    callback, param_dict = resolver.resolve_error_handler(500)
  File "/home/pyvip/.virtualenvs/mysites/lib/python3.6/site-packages/django/urls/resolvers.py", line 546, in resolve_error_handler
    callback = getattr(self.urlconf_module, 'handler%s' % view_type, None)
  File "/home/pyvip/.virtualenvs/mysites/lib/python3.6/site-packages/django/utils/functional.py", line 37, in __get__
    res = instance.__dict__[self.name] = self.func(instance)
  File "/home/pyvip/.virtualenvs/mysites/lib/python3.6/site-packages/django/urls/resolvers.py", line 526, in urlconf_module
    return import_module(self.urlconf_name)
  File "/home/pyvip/.virtualenvs/mysites/lib/python3.6/importlib/__init__.py", line 126, in import_module
    return _bootstrap._gcd_import(name[level:], package, level)
  File "<frozen importlib._bootstrap>", line 994, in _gcd_import
  File "<frozen importlib._bootstrap>", line 971, in _find_and_load
  File "<frozen importlib._bootstrap>", line 955, in _find_and_load_unlocked
  File "<frozen importlib._bootstrap>", line 665, in _load_unlocked
  File "<frozen importlib._bootstrap_external>", line 678, in exec_module
  File "<frozen importlib._bootstrap>", line 219, in _call_with_frames_removed
  File "./mysite/urls.py", line 23, in <module>
    path('', include('news.urls')),
  File "/home/pyvip/.virtualenvs/mysites/lib/python3.6/site-packages/django/urls/conf.py", line 34, in include
    urlconf_module = import_module(urlconf_module)
  File "/home/pyvip/.virtualenvs/mysites/lib/python3.6/importlib/__init__.py", line 126, in import_module
    return _bootstrap._gcd_import(name[level:], package, level)
  File "<frozen importlib._bootstrap>", line 994, in _gcd_import
  File "<frozen importlib._bootstrap>", line 971, in _find_and_load
  File "<frozen importlib._bootstrap>", line 955, in _find_and_load_unlocked
  File "<frozen importlib._bootstrap>", line 665, in _load_unlocked
  File "<frozen importlib._bootstrap_external>", line 678, in exec_module
  File "<frozen importlib._bootstrap>", line 219, in _call_with_frames_removed
  File "/home/pyvip/project/mysite/apps/news/urls.py", line 2, in <module>
    from news import views
  File "/home/pyvip/project/mysite/apps/news/views.py", line 31, in <module>
    @method_decorator(cache_page(timeout=120, cache='page_cache'), name='dispatch')
  File "/home/pyvip/.virtualenvs/mysites/lib/python3.6/site-packages/django/views/decorators/cache.py", line 23, in cache_page
    cache_timeout=timeout, cache_alias=cache, key_prefix=key_prefix
  File "/home/pyvip/.virtualenvs/mysites/lib/python3.6/site-packages/django/utils/decorators.py", line 128, in _make_decorator
    middleware = middleware_class(*m_args, **m_kwargs)
  File "/home/pyvip/.virtualenvs/mysites/lib/python3.6/site-packages/django/middleware/cache.py", line 189, in __init__
    self.cache = caches[self.cache_alias]
  File "/home/pyvip/.virtualenvs/mysites/lib/python3.6/site-packages/django/core/cache/__init__.py", line 76, in __getitem__
    "Could not find config for '%s' in settings.CACHES" % alias
django.core.cache.backends.base.InvalidCacheBackendError: Could not find config for 'page_cache' in settings.CACHES

During handling of the above exception, another exception occurred:

Traceback (most recent call last):
  File "/home/pyvip/.virtualenvs/mysites/lib/python3.6/site-packages/django/core/handlers/exception.py", line 34, in inner
    response = get_response(request)
  File "/home/pyvip/.virtualenvs/mysites/lib/python3.6/site-packages/django/utils/deprecation.py", line 91, in __call__
    response = response or self.get_response(request)
  File "/home/pyvip/.virtualenvs/mysites/lib/python3.6/site-packages/django/core/handlers/exception.py", line 36, in inner
    response = response_for_exception(request, exc)
  File "/home/pyvip/.virtualenvs/mysites/lib/python3.6/site-packages/django/core/handlers/exception.py", line 90, in response_for_exception
    response = handle_uncaught_exception(request, get_resolver(get_urlconf()), sys.exc_info())
  File "/home/pyvip/.virtualenvs/mysites/lib/python3.6/site-packages/django/core/handlers/exception.py", line 128, in handle_uncaught_exception
    callback, param_dict = resolver.resolve_error_handler(500)
  File "/home/pyvip/.virtualenvs/mysites/lib/python3.6/site-packages/django/urls/resolvers.py", line 546, in resolve_error_handler
    callback = getattr(self.urlconf_module, 'handler%s' % view_type, None)
  File "/home/pyvip/.virtualenvs/mysites/lib/python3.6/site-packages/django/utils/functional.py", line 37, in __get__
    res = instance.__dict__[self.name] = self.func(instance)
  File "/home/pyvip/.virtualenvs/mysites/lib/python3.6/site-packages/django/urls/resolvers.py", line 526, in urlconf_module
    return import_module(self.urlconf_name)
  File "/home/pyvip/.virtualenvs/mysites/lib/python3.6/importlib/__init__.py", line 126, in import_module
    return _bootstrap._gcd_import(name[level:], package, level)
  File "<frozen importlib._bootstrap>", line 994, in _gcd_import
  File "<frozen importlib._bootstrap>", line 971, in _find_and_load
  File "<frozen importlib._bootstrap>", line 955, in _find_and_load_unlocked
  File "<frozen importlib._bootstrap>", line 665, in _load_unlocked
  File "<frozen importlib._bootstrap_external>", line 678, in exec_module
  File "<frozen importlib._bootstrap>", line 219, in _call_with_frames_removed
  File "./mysite/urls.py", line 23, in <module>
    path('', include('news.urls')),
  File "/home/pyvip/.virtualenvs/mysites/lib/python3.6/site-packages/django/urls/conf.py", line 34, in include
    urlconf_module = import_module(urlconf_module)
  File "/home/pyvip/.virtualenvs/mysites/lib/python3.6/importlib/__init__.py", line 126, in import_module
    return _bootstrap._gcd_import(name[level:], package, level)
  File "<frozen importlib._bootstrap>", line 994, in _gcd_import
  File "<frozen importlib._bootstrap>", line 971, in _find_and_load
  File "<frozen importlib._bootstrap>", line 955, in _find_and_load_unlocked
  File "<frozen importlib._bootstrap>", line 665, in _load_unlocked
  File "<frozen importlib._bootstrap_external>", line 678, in exec_module
  File "<frozen importlib._bootstrap>", line 219, in _call_with_frames_removed
  File "/home/pyvip/project/mysite/apps/news/urls.py", line 2, in <module>
    from news import views
  File "/home/pyvip/project/mysite/apps/news/views.py", line 31, in <module>
    @method_decorator(cache_page(timeout=120, cache='page_cache'), name='dispatch')
  File "/home/pyvip/.virtualenvs/mysites/lib/python3.6/site-packages/django/views/decorators/cache.py", line 23, in cache_page
    cache_timeout=timeout, cache_alias=cache, key_prefix=key_prefix
  File "/home/pyvip/.virtualenvs/mysites/lib/python3.6/site-packages/django/utils/decorators.py", line 128, in _make_decorator
    middleware = middleware_class(*m_args, **m_kwargs)
  File "/home/pyvip/.virtualenvs/mysites/lib/python3.6/site-packages/django/middleware/cache.py", line 189, in __init__
    self.cache = caches[self.cache_alias]
  File "/home/pyvip/.virtualenvs/mysites/lib/python3.6/site-packages/django/core/cache/__init__.py", line 76, in __getitem__
    "Could not find config for '%s' in settings.CACHES" % alias
django.core.cache.backends.base.InvalidCacheBackendError: Could not find config for 'page_cache' in settings.CACHES

During handling of the above exception, another exception occurred:

Traceback (most recent call last):
  File "/home/pyvip/.virtualenvs/mysites/lib/python3.6/site-packages/django/core/handlers/exception.py", line 34, in inner
    response = get_response(request)
  File "/home/pyvip/.virtualenvs/mysites/lib/python3.6/site-packages/django/utils/deprecation.py", line 91, in __call__
    response = response or self.get_response(request)
  File "/home/pyvip/.virtualenvs/mysites/lib/python3.6/site-packages/django/core/handlers/exception.py", line 36, in inner
    response = response_for_exception(request, exc)
  File "/home/pyvip/.virtualenvs/mysites/lib/python3.6/site-packages/django/core/handlers/exception.py", line 90, in response_for_exception
    response = handle_uncaught_exception(request, get_resolver(get_urlconf()), sys.exc_info())
  File "/home/pyvip/.virtualenvs/mysites/lib/python3.6/site-packages/django/core/handlers/exception.py", line 128, in handle_uncaught_exception
    callback, param_dict = resolver.resolve_error_handler(500)
  File "/home/pyvip/.virtualenvs/mysites/lib/python3.6/site-packages/django/urls/resolvers.py", line 546, in resolve_error_handler
    callback = getattr(self.urlconf_module, 'handler%s' % view_type, None)
  File "/home/pyvip/.virtualenvs/mysites/lib/python3.6/site-packages/django/utils/functional.py", line 37, in __get__
    res = instance.__dict__[self.name] = self.func(instance)
  File "/home/pyvip/.virtualenvs/mysites/lib/python3.6/site-packages/django/urls/resolvers.py", line 526, in urlconf_module
    return import_module(self.urlconf_name)
  File "/home/pyvip/.virtualenvs/mysites/lib/python3.6/importlib/__init__.py", line 126, in import_module
    return _bootstrap._gcd_import(name[level:], package, level)
  File "<frozen importlib._bootstrap>", line 994, in _gcd_import
  File "<frozen importlib._bootstrap>", line 971, in _find_and_load
  File "<frozen importlib._bootstrap>", line 955, in _find_and_load_unlocked
  File "<frozen importlib._bootstrap>", line 665, in _load_unlocked
  File "<frozen importlib._bootstrap_external>", line 678, in exec_module
  File "<frozen importlib._bootstrap>", line 219, in _call_with_frames_removed
  File "./mysite/urls.py", line 23, in <module>
    path('', include('news.urls')),
  File "/home/pyvip/.virtualenvs/mysites/lib/python3.6/site-packages/django/urls/conf.py", line 34, in include
    urlconf_module = import_module(urlconf_module)
  File "/home/pyvip/.virtualenvs/mysites/lib/python3.6/importlib/__init__.py", line 126, in import_module
    return _bootstrap._gcd_import(name[level:], package, level)
  File "<frozen importlib._bootstrap>", line 994, in _gcd_import
  File "<frozen importlib._bootstrap>", line 971, in _find_and_load
  File "<frozen importlib._bootstrap>", line 955, in _find_and_load_unlocked
  File "<frozen importlib._bootstrap>", line 665, in _load_unlocked
  File "<frozen importlib._bootstrap_external>", line 678, in exec_module
  File "<frozen importlib._bootstrap>", line 219, in _call_with_frames_removed
  File "/home/pyvip/project/mysite/apps/news/urls.py", line 2, in <module>
    from news import views
  File "/home/pyvip/project/mysite/apps/news/views.py", line 31, in <module>
    @method_decorator(cache_page(timeout=120, cache='page_cache'), name='dispatch')
  File "/home/pyvip/.virtualenvs/mysites/lib/python3.6/site-packages/django/views/decorators/cache.py", line 23, in cache_page
    cache_timeout=timeout, cache_alias=cache, key_prefix=key_prefix
  File "/home/pyvip/.virtualenvs/mysites/lib/python3.6/site-packages/django/utils/decorators.py", line 128, in _make_decorator
    middleware = middleware_class(*m_args, **m_kwargs)
  File "/home/pyvip/.virtualenvs/mysites/lib/python3.6/site-packages/django/middleware/cache.py", line 189, in __init__
    self.cache = caches[self.cache_alias]
  File "/home/pyvip/.virtualenvs/mysites/lib/python3.6/site-packages/django/core/cache/__init__.py", line 76, in __getitem__
    "Could not find config for '%s' in settings.CACHES" % alias
django.core.cache.backends.base.InvalidCacheBackendError: Could not find config for 'page_cache' in settings.CACHES

During handling of the above exception, another exception occurred:

Traceback (most recent call last):
  File "/home/pyvip/.virtualenvs/mysites/lib/python3.6/site-packages/django/core/handlers/exception.py", line 34, in inner
    response = get_response(request)
  File "/home/pyvip/.virtualenvs/mysites/lib/python3.6/site-packages/django/utils/deprecation.py", line 91, in __call__
    response = response or self.get_response(request)
  File "/home/pyvip/.virtualenvs/mysites/lib/python3.6/site-packages/django/core/handlers/exception.py", line 36, in inner
    response = response_for_exception(request, exc)
  File "/home/pyvip/.virtualenvs/mysites/lib/python3.6/site-packages/django/core/handlers/exception.py", line 90, in response_for_exception
    response = handle_uncaught_exception(request, get_resolver(get_urlconf()), sys.exc_info())
  File "/home/pyvip/.virtualenvs/mysites/lib/python3.6/site-packages/django/core/handlers/exception.py", line 128, in handle_uncaught_exception
    callback, param_dict = resolver.resolve_error_handler(500)
  File "/home/pyvip/.virtualenvs/mysites/lib/python3.6/site-packages/django/urls/resolvers.py", line 546, in resolve_error_handler
    callback = getattr(self.urlconf_module, 'handler%s' % view_type, None)
  File "/home/pyvip/.virtualenvs/mysites/lib/python3.6/site-packages/django/utils/functional.py", line 37, in __get__
    res = instance.__dict__[self.name] = self.func(instance)
  File "/home/pyvip/.virtualenvs/mysites/lib/python3.6/site-packages/django/urls/resolvers.py", line 526, in urlconf_module
    return import_module(self.urlconf_name)
  File "/home/pyvip/.virtualenvs/mysites/lib/python3.6/importlib/__init__.py", line 126, in import_module
    return _bootstrap._gcd_import(name[level:], package, level)
  File "<frozen importlib._bootstrap>", line 994, in _gcd_import
  File "<frozen importlib._bootstrap>", line 971, in _find_and_load
  File "<frozen importlib._bootstrap>", line 955, in _find_and_load_unlocked
  File "<frozen importlib._bootstrap>", line 665, in _load_unlocked
  File "<frozen importlib._bootstrap_external>", line 678, in exec_module
  File "<frozen importlib._bootstrap>", line 219, in _call_with_frames_removed
  File "./mysite/urls.py", line 23, in <module>
    path('', include('news.urls')),
  File "/home/pyvip/.virtualenvs/mysites/lib/python3.6/site-packages/django/urls/conf.py", line 34, in include
    urlconf_module = import_module(urlconf_module)
  File "/home/pyvip/.virtualenvs/mysites/lib/python3.6/importlib/__init__.py", line 126, in import_module
    return _bootstrap._gcd_import(name[level:], package, level)
  File "<frozen importlib._bootstrap>", line 994, in _gcd_import
  File "<frozen importlib._bootstrap>", line 971, in _find_and_load
  File "<frozen importlib._bootstrap>", line 955, in _find_and_load_unlocked
  File "<frozen importlib._bootstrap>", line 665, in _load_unlocked
  File "<frozen importlib._bootstrap_external>", line 678, in exec_module
  File "<frozen importlib._bootstrap>", line 219, in _call_with_frames_removed
  File "/home/pyvip/project/mysite/apps/news/urls.py", line 2, in <module>
    from news import views
  File "/home/pyvip/project/mysite/apps/news/views.py", line 31, in <module>
    @method_decorator(cache_page(timeout=120, cache='page_cache'), name='dispatch')
  File "/home/pyvip/.virtualenvs/mysites/lib/python3.6/site-packages/django/views/decorators/cache.py", line 23, in cache_page
    cache_timeout=timeout, cache_alias=cache, key_prefix=key_prefix
  File "/home/pyvip/.virtualenvs/mysites/lib/python3.6/site-packages/django/utils/decorators.py", line 128, in _make_decorator
    middleware = middleware_class(*m_args, **m_kwargs)
  File "/home/pyvip/.virtualenvs/mysites/lib/python3.6/site-packages/django/middleware/cache.py", line 189, in __init__
    self.cache = caches[self.cache_alias]
  File "/home/pyvip/.virtualenvs/mysites/lib/python3.6/site-packages/django/core/cache/__init__.py", line 76, in __getitem__
    "Could not find config for '%s' in settings.CACHES" % alias
django.core.cache.backends.base.InvalidCacheBackendError: Could not find config for 'page_cache' in settings.CACHES

During handling of the above exception, another exception occurred:

Traceback (most recent call last):
  File "/home/pyvip/.virtualenvs/mysites/lib/python3.6/site-packages/django/core/handlers/exception.py", line 34, in inner
    response = get_response(request)
  File "/home/pyvip/.virtualenvs/mysites/lib/python3.6/site-packages/django/utils/deprecation.py", line 91, in __call__
    response = response or self.get_response(request)
  File "/home/pyvip/.virtualenvs/mysites/lib/python3.6/site-packages/django/core/handlers/exception.py", line 36, in inner
    response = response_for_exception(request, exc)
  File "/home/pyvip/.virtualenvs/mysites/lib/python3.6/site-packages/django/core/handlers/exception.py", line 90, in response_for_exception
    response = handle_uncaught_exception(request, get_resolver(get_urlconf()), sys.exc_info())
  File "/home/pyvip/.virtualenvs/mysites/lib/python3.6/site-packages/django/core/handlers/exception.py", line 128, in handle_uncaught_exception
    callback, param_dict = resolver.resolve_error_handler(500)
  File "/home/pyvip/.virtualenvs/mysites/lib/python3.6/site-packages/django/urls/resolvers.py", line 546, in resolve_error_handler
    callback = getattr(self.urlconf_module, 'handler%s' % view_type, None)
  File "/home/pyvip/.virtualenvs/mysites/lib/python3.6/site-packages/django/utils/functional.py", line 37, in __get__
    res = instance.__dict__[self.name] = self.func(instance)
  File "/home/pyvip/.virtualenvs/mysites/lib/python3.6/site-packages/django/urls/resolvers.py", line 526, in urlconf_module
    return import_module(self.urlconf_name)
  File "/home/pyvip/.virtualenvs/mysites/lib/python3.6/importlib/__init__.py", line 126, in import_module
    return _bootstrap._gcd_import(name[level:], package, level)
  File "<frozen importlib._bootstrap>", line 994, in _gcd_import
  File "<frozen importlib._bootstrap>", line 971, in _find_and_load
  File "<frozen importlib._bootstrap>", line 955, in _find_and_load_unlocked
  File "<frozen importlib._bootstrap>", line 665, in _load_unlocked
  File "<frozen importlib._bootstrap_external>", line 678, in exec_module
  File "<frozen importlib._bootstrap>", line 219, in _call_with_frames_removed
  File "./mysite/urls.py", line 23, in <module>
    path('', include('news.urls')),
  File "/home/pyvip/.virtualenvs/mysites/lib/python3.6/site-packages/django/urls/conf.py", line 34, in include
    urlconf_module = import_module(urlconf_module)
  File "/home/pyvip/.virtualenvs/mysites/lib/python3.6/importlib/__init__.py", line 126, in import_module
    return _bootstrap._gcd_import(name[level:], package, level)
  File "<frozen importlib._bootstrap>", line 994, in _gcd_import
  File "<frozen importlib._bootstrap>", line 971, in _find_and_load
  File "<frozen importlib._bootstrap>", line 955, in _find_and_load_unlocked
  File "<frozen importlib._bootstrap>", line 665, in _load_unlocked
  File "<frozen importlib._bootstrap_external>", line 678, in exec_module
  File "<frozen importlib._bootstrap>", line 219, in _call_with_frames_removed
  File "/home/pyvip/project/mysite/apps/news/urls.py", line 2, in <module>
    from news import views
  File "/home/pyvip/project/mysite/apps/news/views.py", line 31, in <module>
    @method_decorator(cache_page(timeout=120, cache='page_cache'), name='dispatch')
  File "/home/pyvip/.virtualenvs/mysites/lib/python3.6/site-packages/django/views/decorators/cache.py", line 23, in cache_page
    cache_timeout=timeout, cache_alias=cache, key_prefix=key_prefix
  File "/home/pyvip/.virtualenvs/mysites/lib/python3.6/site-packages/django/utils/decorators.py", line 128, in _make_decorator
    middleware = middleware_class(*m_args, **m_kwargs)
  File "/home/pyvip/.virtualenvs/mysites/lib/python3.6/site-packages/django/middleware/cache.py", line 189, in __init__
    self.cache = caches[self.cache_alias]
  File "/home/pyvip/.virtualenvs/mysites/lib/python3.6/site-packages/django/core/cache/__init__.py", line 76, in __getitem__
    "Could not find config for '%s' in settings.CACHES" % alias
django.core.cache.backends.base.InvalidCacheBackendError: Could not find config for 'page_cache' in settings.CACHES

During handling of the above exception, another exception occurred:

Traceback (most recent call last):
  File "/home/pyvip/.virtualenvs/mysites/lib/python3.6/site-packages/django/core/handlers/exception.py", line 34, in inner
    response = get_response(request)
  File "/home/pyvip/.virtualenvs/mysites/lib/python3.6/site-packages/django/utils/deprecation.py", line 91, in __call__
    response = response or self.get_response(request)
  File "/home/pyvip/.virtualenvs/mysites/lib/python3.6/site-packages/django/core/handlers/exception.py", line 36, in inner
    response = response_for_exception(request, exc)
  File "/home/pyvip/.virtualenvs/mysites/lib/python3.6/site-packages/django/core/handlers/exception.py", line 90, in response_for_exception
    response = handle_uncaught_exception(request, get_resolver(get_urlconf()), sys.exc_info())
  File "/home/pyvip/.virtualenvs/mysites/lib/python3.6/site-packages/django/core/handlers/exception.py", line 128, in handle_uncaught_exception
    callback, param_dict = resolver.resolve_error_handler(500)
  File "/home/pyvip/.virtualenvs/mysites/lib/python3.6/site-packages/django/urls/resolvers.py", line 546, in resolve_error_handler
    callback = getattr(self.urlconf_module, 'handler%s' % view_type, None)
  File "/home/pyvip/.virtualenvs/mysites/lib/python3.6/site-packages/django/utils/functional.py", line 37, in __get__
    res = instance.__dict__[self.name] = self.func(instance)
  File "/home/pyvip/.virtualenvs/mysites/lib/python3.6/site-packages/django/urls/resolvers.py", line 526, in urlconf_module
    return import_module(self.urlconf_name)
  File "/home/pyvip/.virtualenvs/mysites/lib/python3.6/importlib/__init__.py", line 126, in import_module
    return _bootstrap._gcd_import(name[level:], package, level)
  File "<frozen importlib._bootstrap>", line 994, in _gcd_import
  File "<frozen importlib._bootstrap>", line 971, in _find_and_load
  File "<frozen importlib._bootstrap>", line 955, in _find_and_load_unlocked
  File "<frozen importlib._bootstrap>", line 665, in _load_unlocked
  File "<frozen importlib._bootstrap_external>", line 678, in exec_module
  File "<frozen importlib._bootstrap>", line 219, in _call_with_frames_removed
  File "./mysite/urls.py", line 23, in <module>
    path('', include('news.urls')),
  File "/home/pyvip/.virtualenvs/mysites/lib/python3.6/site-packages/django/urls/conf.py", line 34, in include
    urlconf_module = import_module(urlconf_module)
  File "/home/pyvip/.virtualenvs/mysites/lib/python3.6/importlib/__init__.py", line 126, in import_module
    return _bootstrap._gcd_import(name[level:], package, level)
  File "<frozen importlib._bootstrap>", line 994, in _gcd_import
  File "<frozen importlib._bootstrap>", line 971, in _find_and_load
  File "<frozen importlib._bootstrap>", line 955, in _find_and_load_unlocked
  File "<frozen importlib._bootstrap>", line 665, in _load_unlocked
  File "<frozen importlib._bootstrap_external>", line 678, in exec_module
  File "<frozen importlib._bootstrap>", line 219, in _call_with_frames_removed
  File "/home/pyvip/project/mysite/apps/news/urls.py", line 2, in <module>
    from news import views
  File "/home/pyvip/project/mysite/apps/news/views.py", line 31, in <module>
    @method_decorator(cache_page(timeout=120, cache='page_cache'), name='dispatch')
  File "/home/pyvip/.virtualenvs/mysites/lib/python3.6/site-packages/django/views/decorators/cache.py", line 23, in cache_page
    cache_timeout=timeout, cache_alias=cache, key_prefix=key_prefix
  File "/home/pyvip/.virtualenvs/mysites/lib/python3.6/site-packages/django/utils/decorators.py", line 128, in _make_decorator
    middleware = middleware_class(*m_args, **m_kwargs)
  File "/home/pyvip/.virtualenvs/mysites/lib/python3.6/site-packages/django/middleware/cache.py", line 189, in __init__
    self.cache = caches[self.cache_alias]
  File "/home/pyvip/.virtualenvs/mysites/lib/python3.6/site-packages/django/core/cache/__init__.py", line 76, in __getitem__
    "Could not find config for '%s' in settings.CACHES" % alias
django.core.cache.backends.base.InvalidCacheBackendError: Could not find config for 'page_cache' in settings.CACHES

During handling of the above exception, another exception occurred:

Traceback (most recent call last):
  File "/home/pyvip/.virtualenvs/mysites/lib/python3.6/site-packages/django/core/handlers/exception.py", line 34, in inner
    response = get_response(request)
  File "/home/pyvip/.virtualenvs/mysites/lib/python3.6/site-packages/django/utils/deprecation.py", line 91, in __call__
    response = response or self.get_response(request)
  File "/home/pyvip/.virtualenvs/mysites/lib/python3.6/site-packages/django/core/handlers/exception.py", line 36, in inner
    response = response_for_exception(request, exc)
  File "/home/pyvip/.virtualenvs/mysites/lib/python3.6/site-packages/django/core/handlers/exception.py", line 90, in response_for_exception
    response = handle_uncaught_exception(request, get_resolver(get_urlconf()), sys.exc_info())
  File "/home/pyvip/.virtualenvs/mysites/lib/python3.6/site-packages/django/core/handlers/exception.py", line 128, in handle_uncaught_exception
    callback, param_dict = resolver.resolve_error_handler(500)
  File "/home/pyvip/.virtualenvs/mysites/lib/python3.6/site-packages/django/urls/resolvers.py", line 546, in resolve_error_handler
    callback = getattr(self.urlconf_module, 'handler%s' % view_type, None)
  File "/home/pyvip/.virtualenvs/mysites/lib/python3.6/site-packages/django/utils/functional.py", line 37, in __get__
    res = instance.__dict__[self.name] = self.func(instance)
  File "/home/pyvip/.virtualenvs/mysites/lib/python3.6/site-packages/django/urls/resolvers.py", line 526, in urlconf_module
    return import_module(self.urlconf_name)
  File "/home/pyvip/.virtualenvs/mysites/lib/python3.6/importlib/__init__.py", line 126, in import_module
    return _bootstrap._gcd_import(name[level:], package, level)
  File "<frozen importlib._bootstrap>", line 994, in _gcd_import
  File "<frozen importlib._bootstrap>", line 971, in _find_and_load
  File "<frozen importlib._bootstrap>", line 955, in _find_and_load_unlocked
  File "<frozen importlib._bootstrap>", line 665, in _load_unlocked
  File "<frozen importlib._bootstrap_external>", line 678, in exec_module
  File "<frozen importlib._bootstrap>", line 219, in _call_with_frames_removed
  File "./mysite/urls.py", line 23, in <module>
    path('', include('news.urls')),
  File "/home/pyvip/.virtualenvs/mysites/lib/python3.6/site-packages/django/urls/conf.py", line 34, in include
    urlconf_module = import_module(urlconf_module)
  File "/home/pyvip/.virtualenvs/mysites/lib/python3.6/importlib/__init__.py", line 126, in import_module
    return _bootstrap._gcd_import(name[level:], package, level)
  File "<frozen importlib._bootstrap>", line 994, in _gcd_import
  File "<frozen importlib._bootstrap>", line 971, in _find_and_load
  File "<frozen importlib._bootstrap>", line 955, in _find_and_load_unlocked
  File "<frozen importlib._bootstrap>", line 665, in _load_unlocked
  File "<frozen importlib._bootstrap_external>", line 678, in exec_module
  File "<frozen importlib._bootstrap>", line 219, in _call_with_frames_removed
  File "/home/pyvip/project/mysite/apps/news/urls.py", line 2, in <module>
    from news import views
  File "/home/pyvip/project/mysite/apps/news/views.py", line 31, in <module>
    @method_decorator(cache_page(timeout=120, cache='page_cache'), name='dispatch')
  File "/home/pyvip/.virtualenvs/mysites/lib/python3.6/site-packages/django/views/decorators/cache.py", line 23, in cache_page
    cache_timeout=timeout, cache_alias=cache, key_prefix=key_prefix
  File "/home/pyvip/.virtualenvs/mysites/lib/python3.6/site-packages/django/utils/decorators.py", line 128, in _make_decorator
    middleware = middleware_class(*m_args, **m_kwargs)
  File "/home/pyvip/.virtualenvs/mysites/lib/python3.6/site-packages/django/middleware/cache.py", line 189, in __init__
    self.cache = caches[self.cache_alias]
  File "/home/pyvip/.virtualenvs/mysites/lib/python3.6/site-packages/django/core/cache/__init__.py", line 76, in __getitem__
    "Could not find config for '%s' in settings.CACHES" % alias
django.core.cache.backends.base.InvalidCacheBackendError: Could not find config for 'page_cache' in settings.CACHES

During handling of the above exception, another exception occurred:

Traceback (most recent call last):
  File "/home/pyvip/.virtualenvs/mysites/lib/python3.6/site-packages/django/core/handlers/exception.py", line 34, in inner
    response = get_response(request)
  File "/home/pyvip/.virtualenvs/mysites/lib/python3.6/site-packages/django/utils/deprecation.py", line 91, in __call__
    response = response or self.get_response(request)
  File "/home/pyvip/.virtualenvs/mysites/lib/python3.6/site-packages/django/core/handlers/exception.py", line 36, in inner
    response = response_for_exception(request, exc)
  File "/home/pyvip/.virtualenvs/mysites/lib/python3.6/site-packages/django/core/handlers/exception.py", line 90, in response_for_exception
    response = handle_uncaught_exception(request, get_resolver(get_urlconf()), sys.exc_info())
  File "/home/pyvip/.virtualenvs/mysites/lib/python3.6/site-packages/django/core/handlers/exception.py", line 128, in handle_uncaught_exception
    callback, param_dict = resolver.resolve_error_handler(500)
  File "/home/pyvip/.virtualenvs/mysites/lib/python3.6/site-packages/django/urls/resolvers.py", line 546, in resolve_error_handler
    callback = getattr(self.urlconf_module, 'handler%s' % view_type, None)
  File "/home/pyvip/.virtualenvs/mysites/lib/python3.6/site-packages/django/utils/functional.py", line 37, in __get__
    res = instance.__dict__[self.name] = self.func(instance)
  File "/home/pyvip/.virtualenvs/mysites/lib/python3.6/site-packages/django/urls/resolvers.py", line 526, in urlconf_module
    return import_module(self.urlconf_name)
  File "/home/pyvip/.virtualenvs/mysites/lib/python3.6/importlib/__init__.py", line 126, in import_module
    return _bootstrap._gcd_import(name[level:], package, level)
  File "<frozen importlib._bootstrap>", line 994, in _gcd_import
  File "<frozen importlib._bootstrap>", line 971, in _find_and_load
  File "<frozen importlib._bootstrap>", line 955, in _find_and_load_unlocked
  File "<frozen importlib._bootstrap>", line 665, in _load_unlocked
  File "<frozen importlib._bootstrap_external>", line 678, in exec_module
  File "<frozen importlib._bootstrap>", line 219, in _call_with_frames_removed
  File "./mysite/urls.py", line 23, in <module>
    path('', include('news.urls')),
  File "/home/pyvip/.virtualenvs/mysites/lib/python3.6/site-packages/django/urls/conf.py", line 34, in include
    urlconf_module = import_module(urlconf_module)
  File "/home/pyvip/.virtualenvs/mysites/lib/python3.6/importlib/__init__.py", line 126, in import_module
    return _bootstrap._gcd_import(name[level:], package, level)
  File "<frozen importlib._bootstrap>", line 994, in _gcd_import
  File "<frozen importlib._bootstrap>", line 971, in _find_and_load
  File "<frozen importlib._bootstrap>", line 955, in _find_and_load_unlocked
  File "<frozen importlib._bootstrap>", line 665, in _load_unlocked
  File "<frozen importlib._bootstrap_external>", line 678, in exec_module
  File "<frozen importlib._bootstrap>", line 219, in _call_with_frames_removed
  File "/home/pyvip/project/mysite/apps/news/urls.py", line 2, in <module>
    from news import views
  File "/home/pyvip/project/mysite/apps/news/views.py", line 31, in <module>
    @method_decorator(cache_page(timeout=120, cache='page_cache'), name='dispatch')
  File "/home/pyvip/.virtualenvs/mysites/lib/python3.6/site-packages/django/views/decorators/cache.py", line 23, in cache_page
    cache_timeout=timeout, cache_alias=cache, key_prefix=key_prefix
  File "/home/pyvip/.virtualenvs/mysites/lib/python3.6/site-packages/django/utils/decorators.py", line 128, in _make_decorator
    middleware = middleware_class(*m_args, **m_kwargs)
  File "/home/pyvip/.virtualenvs/mysites/lib/python3.6/site-packages/django/middleware/cache.py", line 189, in __init__
    self.cache = caches[self.cache_alias]
  File "/home/pyvip/.virtualenvs/mysites/lib/python3.6/site-packages/django/core/cache/__init__.py", line 76, in __getitem__
    "Could not find config for '%s' in settings.CACHES" % alias
django.core.cache.backends.base.InvalidCacheBackendError: Could not find config for 'page_cache' in settings.CACHES

During handling of the above exception, another exception occurred:

Traceback (most recent call last):
  File "/home/pyvip/.virtualenvs/mysites/lib/python3.6/site-packages/django/core/handlers/wsgi.py", line 142, in __call__
    response = self.get_response(request)
  File "/home/pyvip/.virtualenvs/mysites/lib/python3.6/site-packages/django/core/handlers/base.py", line 78, in get_response
    response = self._middleware_chain(request)
  File "/home/pyvip/.virtualenvs/mysites/lib/python3.6/site-packages/django/core/handlers/exception.py", line 36, in inner
    response = response_for_exception(request, exc)
  File "/home/pyvip/.virtualenvs/mysites/lib/python3.6/site-packages/django/core/handlers/exception.py", line 90, in response_for_exception
    response = handle_uncaught_exception(request, get_resolver(get_urlconf()), sys.exc_info())
  File "/home/pyvip/.virtualenvs/mysites/lib/python3.6/site-packages/django/core/handlers/exception.py", line 128, in handle_uncaught_exception
    callback, param_dict = resolver.resolve_error_handler(500)
  File "/home/pyvip/.virtualenvs/mysites/lib/python3.6/site-packages/django/urls/resolvers.py", line 546, in resolve_error_handler
    callback = getattr(self.urlconf_module, 'handler%s' % view_type, None)
  File "/home/pyvip/.virtualenvs/mysites/lib/python3.6/site-packages/django/utils/functional.py", line 37, in __get__
    res = instance.__dict__[self.name] = self.func(instance)
  File "/home/pyvip/.virtualenvs/mysites/lib/python3.6/site-packages/django/urls/resolvers.py", line 526, in urlconf_module
    return import_module(self.urlconf_name)
  File "/home/pyvip/.virtualenvs/mysites/lib/python3.6/importlib/__init__.py", line 126, in import_module
    return _bootstrap._gcd_import(name[level:], package, level)
  File "<frozen importlib._bootstrap>", line 994, in _gcd_import
  File "<frozen importlib._bootstrap>", line 971, in _find_and_load
  File "<frozen importlib._bootstrap>", line 955, in _find_and_load_unlocked
  File "<frozen importlib._bootstrap>", line 665, in _load_unlocked
  File "<frozen importlib._bootstrap_external>", line 678, in exec_module
  File "<frozen importlib._bootstrap>", line 219, in _call_with_frames_removed
  File "./mysite/urls.py", line 23, in <module>
    path('', include('news.urls')),
  File "/home/pyvip/.virtualenvs/mysites/lib/python3.6/site-packages/django/urls/conf.py", line 34, in include
    urlconf_module = import_module(urlconf_module)
  File "/home/pyvip/.virtualenvs/mysites/lib/python3.6/importlib/__init__.py", line 126, in import_module
    return _bootstrap._gcd_import(name[level:], package, level)
  File "<frozen importlib._bootstrap>", line 994, in _gcd_import
  File "<frozen importlib._bootstrap>", line 971, in _find_and_load
  File "<frozen importlib._bootstrap>", line 955, in _find_and_load_unlocked
  File "<frozen importlib._bootstrap>", line 665, in _load_unlocked
  File "<frozen importlib._bootstrap_external>", line 678, in exec_module
  File "<frozen importlib._bootstrap>", line 219, in _call_with_frames_removed
  File "/home/pyvip/project/mysite/apps/news/urls.py", line 2, in <module>
    from news import views
  File "/home/pyvip/project/mysite/apps/news/views.py", line 31, in <module>
    @method_decorator(cache_page(timeout=120, cache='page_cache'), name='dispatch')
  File "/home/pyvip/.virtualenvs/mysites/lib/python3.6/site-packages/django/views/decorators/cache.py", line 23, in cache_page
    cache_timeout=timeout, cache_alias=cache, key_prefix=key_prefix
  File "/home/pyvip/.virtualenvs/mysites/lib/python3.6/site-packages/django/utils/decorators.py", line 128, in _make_decorator
    middleware = middleware_class(*m_args, **m_kwargs)
  File "/home/pyvip/.virtualenvs/mysites/lib/python3.6/site-packages/django/middleware/cache.py", line 189, in __init__
    self.cache = caches[self.cache_alias]
  File "/home/pyvip/.virtualenvs/mysites/lib/python3.6/site-packages/django/core/cache/__init__.py", line 76, in __getitem__
    "Could not find config for '%s' in settings.CACHES" % alias
django.core.cache.backends.base.InvalidCacheBackendError: Could not find config for 'page_cache' in settings.CACHES
[pid: 14348|app: 0|req: 1/1] 127.0.0.1 () {32 vars in 343 bytes} [Mon May 27 23:43:57 2019] GET / => generated 0 bytes in 815 msecs (HTTP/1.1 500) 0 headers in 0 bytes (0 switches on core 0)
SIGINT/SIGQUIT received...killing workers...
worker 1 buried after 1 seconds
goodbye to uWSGI.
*** Starting uWSGI 2.0.18 (64bit) on [Mon May 27 23:46:28 2019] ***
compiled with version: 7.3.0 on 26 May 2019 07:39:13
os: Linux-4.15.0-36-generic #39-Ubuntu SMP Mon Sep 24 16:19:09 UTC 2018
nodename: VIP
machine: x86_64
clock source: unix
pcre jit disabled
detected number of CPU cores: 1
current working directory: /home/pyvip/project/mysite/deploy
writing pidfile to uwsgi.pid
detected binary path: /home/pyvip/.virtualenvs/mysites/bin/uwsgi
chdir() to /home/pyvip/project/mysite
your processes number limit is 3705
your memory page size is 4096 bytes
detected max file descriptor number: 1024
lock engine: pthread robust mutexes
thunder lock: disabled (you can enable it with --thunder-lock)
uwsgi socket 0 bound to TCP address 10.0.2.15:8000 fd 3
Python version: 3.6.6 (default, Sep 12 2018, 18:26:19)  [GCC 8.0.1 20180414 (experimental) [trunk revision 259383]]
Set PythonHome to /home/pyvip/.virtualenvs/mysites
Python main interpreter initialized at 0x560ac9a7aa60
python threads support enabled
your server socket listen backlog is limited to 100 connections
your mercy for graceful operations on workers is 60 seconds
mapped 145840 bytes (142 KB) for 1 cores
*** Operational MODE: single process ***
WSGI app 0 (mountpoint='') ready in 0 seconds on interpreter 0x560ac9a7aa60 pid: 14484 (default app)
*** uWSGI is running in multiple interpreter mode ***
spawned uWSGI master process (pid: 14484)
spawned uWSGI worker 1 (pid: 14486, cores: 1)
DAMN ! worker 1 (pid: 14486) died, killed by signal 9 :( trying respawn ...
Respawned uWSGI worker 1 (new pid: 15264)
Tue May 28 17:29:35 2019 - uWSGI worker 1 screams: UAAAAAAH my master disconnected: i will kill myself !!!
*** Starting uWSGI 2.0.18 (64bit) on [Tue Jun  4 18:46:40 2019] ***
compiled with version: 7.3.0 on 26 May 2019 07:39:13
os: Linux-4.15.0-36-generic #39-Ubuntu SMP Mon Sep 24 16:19:09 UTC 2018
nodename: VIP
machine: x86_64
clock source: unix
pcre jit disabled
detected number of CPU cores: 1
current working directory: /home/pyvip/project/mysite/deploy
writing pidfile to uwsgi.pid
detected binary path: /home/pyvip/.virtualenvs/mysites/bin/uwsgi
chdir() to /home/pyvip/project/mysite
your processes number limit is 3705
your memory page size is 4096 bytes
detected max file descriptor number: 1024
lock engine: pthread robust mutexes
thunder lock: disabled (you can enable it with --thunder-lock)
uwsgi socket 0 bound to TCP address 10.0.2.15:8000 fd 3
Python version: 3.6.6 (default, Sep 12 2018, 18:26:19)  [GCC 8.0.1 20180414 (experimental) [trunk revision 259383]]
Set PythonHome to /home/pyvip/.virtualenvs/mysites
Python main interpreter initialized at 0x561107538a60
python threads support enabled
your server socket listen backlog is limited to 100 connections
your mercy for graceful operations on workers is 60 seconds
mapped 145840 bytes (142 KB) for 1 cores
*** Operational MODE: single process ***
WSGI app 0 (mountpoint='') ready in 9 seconds on interpreter 0x561107538a60 pid: 9076 (default app)
*** uWSGI is running in multiple interpreter mode ***
spawned uWSGI master process (pid: 9076)
spawned uWSGI worker 1 (pid: 9078, cores: 1)
Traceback (most recent call last):
  File "/home/pyvip/.virtualenvs/mysites/lib/python3.6/site-packages/django/core/handlers/exception.py", line 34, in inner
    response = get_response(request)
  File "/home/pyvip/.virtualenvs/mysites/lib/python3.6/site-packages/django/core/handlers/base.py", line 111, in _get_response
    resolver_match = resolver.resolve(request.path_info)
  File "/home/pyvip/.virtualenvs/mysites/lib/python3.6/site-packages/django/urls/resolvers.py", line 491, in resolve
    for pattern in self.url_patterns:
  File "/home/pyvip/.virtualenvs/mysites/lib/python3.6/site-packages/django/utils/functional.py", line 37, in __get__
    res = instance.__dict__[self.name] = self.func(instance)
  File "/home/pyvip/.virtualenvs/mysites/lib/python3.6/site-packages/django/urls/resolvers.py", line 533, in url_patterns
    patterns = getattr(self.urlconf_module, "urlpatterns", self.urlconf_module)
  File "/home/pyvip/.virtualenvs/mysites/lib/python3.6/site-packages/django/utils/functional.py", line 37, in __get__
    res = instance.__dict__[self.name] = self.func(instance)
  File "/home/pyvip/.virtualenvs/mysites/lib/python3.6/site-packages/django/urls/resolvers.py", line 526, in urlconf_module
    return import_module(self.urlconf_name)
  File "/home/pyvip/.virtualenvs/mysites/lib/python3.6/importlib/__init__.py", line 126, in import_module
    return _bootstrap._gcd_import(name[level:], package, level)
  File "<frozen importlib._bootstrap>", line 994, in _gcd_import
  File "<frozen importlib._bootstrap>", line 971, in _find_and_load
  File "<frozen importlib._bootstrap>", line 955, in _find_and_load_unlocked
  File "<frozen importlib._bootstrap>", line 665, in _load_unlocked
  File "<frozen importlib._bootstrap_external>", line 678, in exec_module
  File "<frozen importlib._bootstrap>", line 219, in _call_with_frames_removed
  File "./mysite/urls.py", line 23, in <module>
    path('', include('news.urls')),
  File "/home/pyvip/.virtualenvs/mysites/lib/python3.6/site-packages/django/urls/conf.py", line 34, in include
    urlconf_module = import_module(urlconf_module)
  File "/home/pyvip/.virtualenvs/mysites/lib/python3.6/importlib/__init__.py", line 126, in import_module
    return _bootstrap._gcd_import(name[level:], package, level)
  File "<frozen importlib._bootstrap>", line 994, in _gcd_import
  File "<frozen importlib._bootstrap>", line 971, in _find_and_load
  File "<frozen importlib._bootstrap>", line 955, in _find_and_load_unlocked
  File "<frozen importlib._bootstrap>", line 665, in _load_unlocked
  File "<frozen importlib._bootstrap_external>", line 678, in exec_module
  File "<frozen importlib._bootstrap>", line 219, in _call_with_frames_removed
  File "/home/pyvip/project/mysite/apps/news/urls.py", line 2, in <module>
    from news import views
  File "/home/pyvip/project/mysite/apps/news/views.py", line 31, in <module>
    @method_decorator(cache_page(timeout=120, cache='page_cache'), name='dispatch')
  File "/home/pyvip/.virtualenvs/mysites/lib/python3.6/site-packages/django/views/decorators/cache.py", line 23, in cache_page
    cache_timeout=timeout, cache_alias=cache, key_prefix=key_prefix
  File "/home/pyvip/.virtualenvs/mysites/lib/python3.6/site-packages/django/utils/decorators.py", line 128, in _make_decorator
    middleware = middleware_class(*m_args, **m_kwargs)
  File "/home/pyvip/.virtualenvs/mysites/lib/python3.6/site-packages/django/middleware/cache.py", line 189, in __init__
    self.cache = caches[self.cache_alias]
  File "/home/pyvip/.virtualenvs/mysites/lib/python3.6/site-packages/django/core/cache/__init__.py", line 76, in __getitem__
    "Could not find config for '%s' in settings.CACHES" % alias
django.core.cache.backends.base.InvalidCacheBackendError: Could not find config for 'page_cache' in settings.CACHES

During handling of the above exception, another exception occurred:

Traceback (most recent call last):
  File "/home/pyvip/.virtualenvs/mysites/lib/python3.6/site-packages/django/core/handlers/exception.py", line 34, in inner
    response = get_response(request)
  File "/home/pyvip/.virtualenvs/mysites/lib/python3.6/site-packages/django/utils/deprecation.py", line 91, in __call__
    response = response or self.get_response(request)
  File "/home/pyvip/.virtualenvs/mysites/lib/python3.6/site-packages/django/core/handlers/exception.py", line 36, in inner
    response = response_for_exception(request, exc)
  File "/home/pyvip/.virtualenvs/mysites/lib/python3.6/site-packages/django/core/handlers/exception.py", line 90, in response_for_exception
    response = handle_uncaught_exception(request, get_resolver(get_urlconf()), sys.exc_info())
  File "/home/pyvip/.virtualenvs/mysites/lib/python3.6/site-packages/django/core/handlers/exception.py", line 128, in handle_uncaught_exception
    callback, param_dict = resolver.resolve_error_handler(500)
  File "/home/pyvip/.virtualenvs/mysites/lib/python3.6/site-packages/django/urls/resolvers.py", line 546, in resolve_error_handler
    callback = getattr(self.urlconf_module, 'handler%s' % view_type, None)
  File "/home/pyvip/.virtualenvs/mysites/lib/python3.6/site-packages/django/utils/functional.py", line 37, in __get__
    res = instance.__dict__[self.name] = self.func(instance)
  File "/home/pyvip/.virtualenvs/mysites/lib/python3.6/site-packages/django/urls/resolvers.py", line 526, in urlconf_module
    return import_module(self.urlconf_name)
  File "/home/pyvip/.virtualenvs/mysites/lib/python3.6/importlib/__init__.py", line 126, in import_module
    return _bootstrap._gcd_import(name[level:], package, level)
  File "<frozen importlib._bootstrap>", line 994, in _gcd_import
  File "<frozen importlib._bootstrap>", line 971, in _find_and_load
  File "<frozen importlib._bootstrap>", line 955, in _find_and_load_unlocked
  File "<frozen importlib._bootstrap>", line 665, in _load_unlocked
  File "<frozen importlib._bootstrap_external>", line 678, in exec_module
  File "<frozen importlib._bootstrap>", line 219, in _call_with_frames_removed
  File "./mysite/urls.py", line 23, in <module>
    path('', include('news.urls')),
  File "/home/pyvip/.virtualenvs/mysites/lib/python3.6/site-packages/django/urls/conf.py", line 34, in include
    urlconf_module = import_module(urlconf_module)
  File "/home/pyvip/.virtualenvs/mysites/lib/python3.6/importlib/__init__.py", line 126, in import_module
    return _bootstrap._gcd_import(name[level:], package, level)
  File "<frozen importlib._bootstrap>", line 994, in _gcd_import
  File "<frozen importlib._bootstrap>", line 971, in _find_and_load
  File "<frozen importlib._bootstrap>", line 955, in _find_and_load_unlocked
  File "<frozen importlib._bootstrap>", line 665, in _load_unlocked
  File "<frozen importlib._bootstrap_external>", line 678, in exec_module
  File "<frozen importlib._bootstrap>", line 219, in _call_with_frames_removed
  File "/home/pyvip/project/mysite/apps/news/urls.py", line 2, in <module>
    from news import views
  File "/home/pyvip/project/mysite/apps/news/views.py", line 31, in <module>
    @method_decorator(cache_page(timeout=120, cache='page_cache'), name='dispatch')
  File "/home/pyvip/.virtualenvs/mysites/lib/python3.6/site-packages/django/views/decorators/cache.py", line 23, in cache_page
    cache_timeout=timeout, cache_alias=cache, key_prefix=key_prefix
  File "/home/pyvip/.virtualenvs/mysites/lib/python3.6/site-packages/django/utils/decorators.py", line 128, in _make_decorator
    middleware = middleware_class(*m_args, **m_kwargs)
  File "/home/pyvip/.virtualenvs/mysites/lib/python3.6/site-packages/django/middleware/cache.py", line 189, in __init__
    self.cache = caches[self.cache_alias]
  File "/home/pyvip/.virtualenvs/mysites/lib/python3.6/site-packages/django/core/cache/__init__.py", line 76, in __getitem__
    "Could not find config for '%s' in settings.CACHES" % alias
django.core.cache.backends.base.InvalidCacheBackendError: Could not find config for 'page_cache' in settings.CACHES

During handling of the above exception, another exception occurred:

Traceback (most recent call last):
  File "/home/pyvip/.virtualenvs/mysites/lib/python3.6/site-packages/django/core/handlers/exception.py", line 34, in inner
    response = get_response(request)
  File "/home/pyvip/.virtualenvs/mysites/lib/python3.6/site-packages/django/utils/deprecation.py", line 91, in __call__
    response = response or self.get_response(request)
  File "/home/pyvip/.virtualenvs/mysites/lib/python3.6/site-packages/django/core/handlers/exception.py", line 36, in inner
    response = response_for_exception(request, exc)
  File "/home/pyvip/.virtualenvs/mysites/lib/python3.6/site-packages/django/core/handlers/exception.py", line 90, in response_for_exception
    response = handle_uncaught_exception(request, get_resolver(get_urlconf()), sys.exc_info())
  File "/home/pyvip/.virtualenvs/mysites/lib/python3.6/site-packages/django/core/handlers/exception.py", line 128, in handle_uncaught_exception
    callback, param_dict = resolver.resolve_error_handler(500)
  File "/home/pyvip/.virtualenvs/mysites/lib/python3.6/site-packages/django/urls/resolvers.py", line 546, in resolve_error_handler
    callback = getattr(self.urlconf_module, 'handler%s' % view_type, None)
  File "/home/pyvip/.virtualenvs/mysites/lib/python3.6/site-packages/django/utils/functional.py", line 37, in __get__
    res = instance.__dict__[self.name] = self.func(instance)
  File "/home/pyvip/.virtualenvs/mysites/lib/python3.6/site-packages/django/urls/resolvers.py", line 526, in urlconf_module
    return import_module(self.urlconf_name)
  File "/home/pyvip/.virtualenvs/mysites/lib/python3.6/importlib/__init__.py", line 126, in import_module
    return _bootstrap._gcd_import(name[level:], package, level)
  File "<frozen importlib._bootstrap>", line 994, in _gcd_import
  File "<frozen importlib._bootstrap>", line 971, in _find_and_load
  File "<frozen importlib._bootstrap>", line 955, in _find_and_load_unlocked
  File "<frozen importlib._bootstrap>", line 665, in _load_unlocked
  File "<frozen importlib._bootstrap_external>", line 678, in exec_module
  File "<frozen importlib._bootstrap>", line 219, in _call_with_frames_removed
  File "./mysite/urls.py", line 23, in <module>
    path('', include('news.urls')),
  File "/home/pyvip/.virtualenvs/mysites/lib/python3.6/site-packages/django/urls/conf.py", line 34, in include
    urlconf_module = import_module(urlconf_module)
  File "/home/pyvip/.virtualenvs/mysites/lib/python3.6/importlib/__init__.py", line 126, in import_module
    return _bootstrap._gcd_import(name[level:], package, level)
  File "<frozen importlib._bootstrap>", line 994, in _gcd_import
  File "<frozen importlib._bootstrap>", line 971, in _find_and_load
  File "<frozen importlib._bootstrap>", line 955, in _find_and_load_unlocked
  File "<frozen importlib._bootstrap>", line 665, in _load_unlocked
  File "<frozen importlib._bootstrap_external>", line 678, in exec_module
  File "<frozen importlib._bootstrap>", line 219, in _call_with_frames_removed
  File "/home/pyvip/project/mysite/apps/news/urls.py", line 2, in <module>
    from news import views
  File "/home/pyvip/project/mysite/apps/news/views.py", line 31, in <module>
    @method_decorator(cache_page(timeout=120, cache='page_cache'), name='dispatch')
  File "/home/pyvip/.virtualenvs/mysites/lib/python3.6/site-packages/django/views/decorators/cache.py", line 23, in cache_page
    cache_timeout=timeout, cache_alias=cache, key_prefix=key_prefix
  File "/home/pyvip/.virtualenvs/mysites/lib/python3.6/site-packages/django/utils/decorators.py", line 128, in _make_decorator
    middleware = middleware_class(*m_args, **m_kwargs)
  File "/home/pyvip/.virtualenvs/mysites/lib/python3.6/site-packages/django/middleware/cache.py", line 189, in __init__
    self.cache = caches[self.cache_alias]
  File "/home/pyvip/.virtualenvs/mysites/lib/python3.6/site-packages/django/core/cache/__init__.py", line 76, in __getitem__
    "Could not find config for '%s' in settings.CACHES" % alias
django.core.cache.backends.base.InvalidCacheBackendError: Could not find config for 'page_cache' in settings.CACHES

During handling of the above exception, another exception occurred:

Traceback (most recent call last):
  File "/home/pyvip/.virtualenvs/mysites/lib/python3.6/site-packages/django/core/handlers/exception.py", line 34, in inner
    response = get_response(request)
  File "/home/pyvip/.virtualenvs/mysites/lib/python3.6/site-packages/django/utils/deprecation.py", line 91, in __call__
    response = response or self.get_response(request)
  File "/home/pyvip/.virtualenvs/mysites/lib/python3.6/site-packages/django/core/handlers/exception.py", line 36, in inner
    response = response_for_exception(request, exc)
  File "/home/pyvip/.virtualenvs/mysites/lib/python3.6/site-packages/django/core/handlers/exception.py", line 90, in response_for_exception
    response = handle_uncaught_exception(request, get_resolver(get_urlconf()), sys.exc_info())
  File "/home/pyvip/.virtualenvs/mysites/lib/python3.6/site-packages/django/core/handlers/exception.py", line 128, in handle_uncaught_exception
    callback, param_dict = resolver.resolve_error_handler(500)
  File "/home/pyvip/.virtualenvs/mysites/lib/python3.6/site-packages/django/urls/resolvers.py", line 546, in resolve_error_handler
    callback = getattr(self.urlconf_module, 'handler%s' % view_type, None)
  File "/home/pyvip/.virtualenvs/mysites/lib/python3.6/site-packages/django/utils/functional.py", line 37, in __get__
    res = instance.__dict__[self.name] = self.func(instance)
  File "/home/pyvip/.virtualenvs/mysites/lib/python3.6/site-packages/django/urls/resolvers.py", line 526, in urlconf_module
    return import_module(self.urlconf_name)
  File "/home/pyvip/.virtualenvs/mysites/lib/python3.6/importlib/__init__.py", line 126, in import_module
    return _bootstrap._gcd_import(name[level:], package, level)
  File "<frozen importlib._bootstrap>", line 994, in _gcd_import
  File "<frozen importlib._bootstrap>", line 971, in _find_and_load
  File "<frozen importlib._bootstrap>", line 955, in _find_and_load_unlocked
  File "<frozen importlib._bootstrap>", line 665, in _load_unlocked
  File "<frozen importlib._bootstrap_external>", line 678, in exec_module
  File "<frozen importlib._bootstrap>", line 219, in _call_with_frames_removed
  File "./mysite/urls.py", line 23, in <module>
    path('', include('news.urls')),
  File "/home/pyvip/.virtualenvs/mysites/lib/python3.6/site-packages/django/urls/conf.py", line 34, in include
    urlconf_module = import_module(urlconf_module)
  File "/home/pyvip/.virtualenvs/mysites/lib/python3.6/importlib/__init__.py", line 126, in import_module
    return _bootstrap._gcd_import(name[level:], package, level)
  File "<frozen importlib._bootstrap>", line 994, in _gcd_import
  File "<frozen importlib._bootstrap>", line 971, in _find_and_load
  File "<frozen importlib._bootstrap>", line 955, in _find_and_load_unlocked
  File "<frozen importlib._bootstrap>", line 665, in _load_unlocked
  File "<frozen importlib._bootstrap_external>", line 678, in exec_module
  File "<frozen importlib._bootstrap>", line 219, in _call_with_frames_removed
  File "/home/pyvip/project/mysite/apps/news/urls.py", line 2, in <module>
    from news import views
  File "/home/pyvip/project/mysite/apps/news/views.py", line 31, in <module>
    @method_decorator(cache_page(timeout=120, cache='page_cache'), name='dispatch')
  File "/home/pyvip/.virtualenvs/mysites/lib/python3.6/site-packages/django/views/decorators/cache.py", line 23, in cache_page
    cache_timeout=timeout, cache_alias=cache, key_prefix=key_prefix
  File "/home/pyvip/.virtualenvs/mysites/lib/python3.6/site-packages/django/utils/decorators.py", line 128, in _make_decorator
    middleware = middleware_class(*m_args, **m_kwargs)
  File "/home/pyvip/.virtualenvs/mysites/lib/python3.6/site-packages/django/middleware/cache.py", line 189, in __init__
    self.cache = caches[self.cache_alias]
  File "/home/pyvip/.virtualenvs/mysites/lib/python3.6/site-packages/django/core/cache/__init__.py", line 76, in __getitem__
    "Could not find config for '%s' in settings.CACHES" % alias
django.core.cache.backends.base.InvalidCacheBackendError: Could not find config for 'page_cache' in settings.CACHES

During handling of the above exception, another exception occurred:

Traceback (most recent call last):
  File "/home/pyvip/.virtualenvs/mysites/lib/python3.6/site-packages/django/core/handlers/exception.py", line 34, in inner
    response = get_response(request)
  File "/home/pyvip/.virtualenvs/mysites/lib/python3.6/site-packages/django/utils/deprecation.py", line 91, in __call__
    response = response or self.get_response(request)
  File "/home/pyvip/.virtualenvs/mysites/lib/python3.6/site-packages/django/core/handlers/exception.py", line 36, in inner
    response = response_for_exception(request, exc)
  File "/home/pyvip/.virtualenvs/mysites/lib/python3.6/site-packages/django/core/handlers/exception.py", line 90, in response_for_exception
    response = handle_uncaught_exception(request, get_resolver(get_urlconf()), sys.exc_info())
  File "/home/pyvip/.virtualenvs/mysites/lib/python3.6/site-packages/django/core/handlers/exception.py", line 128, in handle_uncaught_exception
    callback, param_dict = resolver.resolve_error_handler(500)
  File "/home/pyvip/.virtualenvs/mysites/lib/python3.6/site-packages/django/urls/resolvers.py", line 546, in resolve_error_handler
    callback = getattr(self.urlconf_module, 'handler%s' % view_type, None)
  File "/home/pyvip/.virtualenvs/mysites/lib/python3.6/site-packages/django/utils/functional.py", line 37, in __get__
    res = instance.__dict__[self.name] = self.func(instance)
  File "/home/pyvip/.virtualenvs/mysites/lib/python3.6/site-packages/django/urls/resolvers.py", line 526, in urlconf_module
    return import_module(self.urlconf_name)
  File "/home/pyvip/.virtualenvs/mysites/lib/python3.6/importlib/__init__.py", line 126, in import_module
    return _bootstrap._gcd_import(name[level:], package, level)
  File "<frozen importlib._bootstrap>", line 994, in _gcd_import
  File "<frozen importlib._bootstrap>", line 971, in _find_and_load
  File "<frozen importlib._bootstrap>", line 955, in _find_and_load_unlocked
  File "<frozen importlib._bootstrap>", line 665, in _load_unlocked
  File "<frozen importlib._bootstrap_external>", line 678, in exec_module
  File "<frozen importlib._bootstrap>", line 219, in _call_with_frames_removed
  File "./mysite/urls.py", line 23, in <module>
    path('', include('news.urls')),
  File "/home/pyvip/.virtualenvs/mysites/lib/python3.6/site-packages/django/urls/conf.py", line 34, in include
    urlconf_module = import_module(urlconf_module)
  File "/home/pyvip/.virtualenvs/mysites/lib/python3.6/importlib/__init__.py", line 126, in import_module
    return _bootstrap._gcd_import(name[level:], package, level)
  File "<frozen importlib._bootstrap>", line 994, in _gcd_import
  File "<frozen importlib._bootstrap>", line 971, in _find_and_load
  File "<frozen importlib._bootstrap>", line 955, in _find_and_load_unlocked
  File "<frozen importlib._bootstrap>", line 665, in _load_unlocked
  File "<frozen importlib._bootstrap_external>", line 678, in exec_module
  File "<frozen importlib._bootstrap>", line 219, in _call_with_frames_removed
  File "/home/pyvip/project/mysite/apps/news/urls.py", line 2, in <module>
    from news import views
  File "/home/pyvip/project/mysite/apps/news/views.py", line 31, in <module>
    @method_decorator(cache_page(timeout=120, cache='page_cache'), name='dispatch')
  File "/home/pyvip/.virtualenvs/mysites/lib/python3.6/site-packages/django/views/decorators/cache.py", line 23, in cache_page
    cache_timeout=timeout, cache_alias=cache, key_prefix=key_prefix
  File "/home/pyvip/.virtualenvs/mysites/lib/python3.6/site-packages/django/utils/decorators.py", line 128, in _make_decorator
    middleware = middleware_class(*m_args, **m_kwargs)
  File "/home/pyvip/.virtualenvs/mysites/lib/python3.6/site-packages/django/middleware/cache.py", line 189, in __init__
    self.cache = caches[self.cache_alias]
  File "/home/pyvip/.virtualenvs/mysites/lib/python3.6/site-packages/django/core/cache/__init__.py", line 76, in __getitem__
    "Could not find config for '%s' in settings.CACHES" % alias
django.core.cache.backends.base.InvalidCacheBackendError: Could not find config for 'page_cache' in settings.CACHES

During handling of the above exception, another exception occurred:

Traceback (most recent call last):
  File "/home/pyvip/.virtualenvs/mysites/lib/python3.6/site-packages/django/core/handlers/exception.py", line 34, in inner
    response = get_response(request)
  File "/home/pyvip/.virtualenvs/mysites/lib/python3.6/site-packages/django/utils/deprecation.py", line 91, in __call__
    response = response or self.get_response(request)
  File "/home/pyvip/.virtualenvs/mysites/lib/python3.6/site-packages/django/core/handlers/exception.py", line 36, in inner
    response = response_for_exception(request, exc)
  File "/home/pyvip/.virtualenvs/mysites/lib/python3.6/site-packages/django/core/handlers/exception.py", line 90, in response_for_exception
    response = handle_uncaught_exception(request, get_resolver(get_urlconf()), sys.exc_info())
  File "/home/pyvip/.virtualenvs/mysites/lib/python3.6/site-packages/django/core/handlers/exception.py", line 128, in handle_uncaught_exception
    callback, param_dict = resolver.resolve_error_handler(500)
  File "/home/pyvip/.virtualenvs/mysites/lib/python3.6/site-packages/django/urls/resolvers.py", line 546, in resolve_error_handler
    callback = getattr(self.urlconf_module, 'handler%s' % view_type, None)
  File "/home/pyvip/.virtualenvs/mysites/lib/python3.6/site-packages/django/utils/functional.py", line 37, in __get__
    res = instance.__dict__[self.name] = self.func(instance)
  File "/home/pyvip/.virtualenvs/mysites/lib/python3.6/site-packages/django/urls/resolvers.py", line 526, in urlconf_module
    return import_module(self.urlconf_name)
  File "/home/pyvip/.virtualenvs/mysites/lib/python3.6/importlib/__init__.py", line 126, in import_module
    return _bootstrap._gcd_import(name[level:], package, level)
  File "<frozen importlib._bootstrap>", line 994, in _gcd_import
  File "<frozen importlib._bootstrap>", line 971, in _find_and_load
  File "<frozen importlib._bootstrap>", line 955, in _find_and_load_unlocked
  File "<frozen importlib._bootstrap>", line 665, in _load_unlocked
  File "<frozen importlib._bootstrap_external>", line 678, in exec_module
  File "<frozen importlib._bootstrap>", line 219, in _call_with_frames_removed
  File "./mysite/urls.py", line 23, in <module>
    path('', include('news.urls')),
  File "/home/pyvip/.virtualenvs/mysites/lib/python3.6/site-packages/django/urls/conf.py", line 34, in include
    urlconf_module = import_module(urlconf_module)
  File "/home/pyvip/.virtualenvs/mysites/lib/python3.6/importlib/__init__.py", line 126, in import_module
    return _bootstrap._gcd_import(name[level:], package, level)
  File "<frozen importlib._bootstrap>", line 994, in _gcd_import
  File "<frozen importlib._bootstrap>", line 971, in _find_and_load
  File "<frozen importlib._bootstrap>", line 955, in _find_and_load_unlocked
  File "<frozen importlib._bootstrap>", line 665, in _load_unlocked
  File "<frozen importlib._bootstrap_external>", line 678, in exec_module
  File "<frozen importlib._bootstrap>", line 219, in _call_with_frames_removed
  File "/home/pyvip/project/mysite/apps/news/urls.py", line 2, in <module>
    from news import views
  File "/home/pyvip/project/mysite/apps/news/views.py", line 31, in <module>
    @method_decorator(cache_page(timeout=120, cache='page_cache'), name='dispatch')
  File "/home/pyvip/.virtualenvs/mysites/lib/python3.6/site-packages/django/views/decorators/cache.py", line 23, in cache_page
    cache_timeout=timeout, cache_alias=cache, key_prefix=key_prefix
  File "/home/pyvip/.virtualenvs/mysites/lib/python3.6/site-packages/django/utils/decorators.py", line 128, in _make_decorator
    middleware = middleware_class(*m_args, **m_kwargs)
  File "/home/pyvip/.virtualenvs/mysites/lib/python3.6/site-packages/django/middleware/cache.py", line 189, in __init__
    self.cache = caches[self.cache_alias]
  File "/home/pyvip/.virtualenvs/mysites/lib/python3.6/site-packages/django/core/cache/__init__.py", line 76, in __getitem__
    "Could not find config for '%s' in settings.CACHES" % alias
django.core.cache.backends.base.InvalidCacheBackendError: Could not find config for 'page_cache' in settings.CACHES

During handling of the above exception, another exception occurred:

Traceback (most recent call last):
  File "/home/pyvip/.virtualenvs/mysites/lib/python3.6/site-packages/django/core/handlers/exception.py", line 34, in inner
    response = get_response(request)
  File "/home/pyvip/.virtualenvs/mysites/lib/python3.6/site-packages/django/utils/deprecation.py", line 91, in __call__
    response = response or self.get_response(request)
  File "/home/pyvip/.virtualenvs/mysites/lib/python3.6/site-packages/django/core/handlers/exception.py", line 36, in inner
    response = response_for_exception(request, exc)
  File "/home/pyvip/.virtualenvs/mysites/lib/python3.6/site-packages/django/core/handlers/exception.py", line 90, in response_for_exception
    response = handle_uncaught_exception(request, get_resolver(get_urlconf()), sys.exc_info())
  File "/home/pyvip/.virtualenvs/mysites/lib/python3.6/site-packages/django/core/handlers/exception.py", line 128, in handle_uncaught_exception
    callback, param_dict = resolver.resolve_error_handler(500)
  File "/home/pyvip/.virtualenvs/mysites/lib/python3.6/site-packages/django/urls/resolvers.py", line 546, in resolve_error_handler
    callback = getattr(self.urlconf_module, 'handler%s' % view_type, None)
  File "/home/pyvip/.virtualenvs/mysites/lib/python3.6/site-packages/django/utils/functional.py", line 37, in __get__
    res = instance.__dict__[self.name] = self.func(instance)
  File "/home/pyvip/.virtualenvs/mysites/lib/python3.6/site-packages/django/urls/resolvers.py", line 526, in urlconf_module
    return import_module(self.urlconf_name)
  File "/home/pyvip/.virtualenvs/mysites/lib/python3.6/importlib/__init__.py", line 126, in import_module
    return _bootstrap._gcd_import(name[level:], package, level)
  File "<frozen importlib._bootstrap>", line 994, in _gcd_import
  File "<frozen importlib._bootstrap>", line 971, in _find_and_load
  File "<frozen importlib._bootstrap>", line 955, in _find_and_load_unlocked
  File "<frozen importlib._bootstrap>", line 665, in _load_unlocked
  File "<frozen importlib._bootstrap_external>", line 678, in exec_module
  File "<frozen importlib._bootstrap>", line 219, in _call_with_frames_removed
  File "./mysite/urls.py", line 23, in <module>
    path('', include('news.urls')),
  File "/home/pyvip/.virtualenvs/mysites/lib/python3.6/site-packages/django/urls/conf.py", line 34, in include
    urlconf_module = import_module(urlconf_module)
  File "/home/pyvip/.virtualenvs/mysites/lib/python3.6/importlib/__init__.py", line 126, in import_module
    return _bootstrap._gcd_import(name[level:], package, level)
  File "<frozen importlib._bootstrap>", line 994, in _gcd_import
  File "<frozen importlib._bootstrap>", line 971, in _find_and_load
  File "<frozen importlib._bootstrap>", line 955, in _find_and_load_unlocked
  File "<frozen importlib._bootstrap>", line 665, in _load_unlocked
  File "<frozen importlib._bootstrap_external>", line 678, in exec_module
  File "<frozen importlib._bootstrap>", line 219, in _call_with_frames_removed
  File "/home/pyvip/project/mysite/apps/news/urls.py", line 2, in <module>
    from news import views
  File "/home/pyvip/project/mysite/apps/news/views.py", line 31, in <module>
    @method_decorator(cache_page(timeout=120, cache='page_cache'), name='dispatch')
  File "/home/pyvip/.virtualenvs/mysites/lib/python3.6/site-packages/django/views/decorators/cache.py", line 23, in cache_page
    cache_timeout=timeout, cache_alias=cache, key_prefix=key_prefix
  File "/home/pyvip/.virtualenvs/mysites/lib/python3.6/site-packages/django/utils/decorators.py", line 128, in _make_decorator
    middleware = middleware_class(*m_args, **m_kwargs)
  File "/home/pyvip/.virtualenvs/mysites/lib/python3.6/site-packages/django/middleware/cache.py", line 189, in __init__
    self.cache = caches[self.cache_alias]
  File "/home/pyvip/.virtualenvs/mysites/lib/python3.6/site-packages/django/core/cache/__init__.py", line 76, in __getitem__
    "Could not find config for '%s' in settings.CACHES" % alias
django.core.cache.backends.base.InvalidCacheBackendError: Could not find config for 'page_cache' in settings.CACHES

During handling of the above exception, another exception occurred:

Traceback (most recent call last):
  File "/home/pyvip/.virtualenvs/mysites/lib/python3.6/site-packages/django/core/handlers/exception.py", line 34, in inner
    response = get_response(request)
  File "/home/pyvip/.virtualenvs/mysites/lib/python3.6/site-packages/django/utils/deprecation.py", line 91, in __call__
    response = response or self.get_response(request)
  File "/home/pyvip/.virtualenvs/mysites/lib/python3.6/site-packages/django/core/handlers/exception.py", line 36, in inner
    response = response_for_exception(request, exc)
  File "/home/pyvip/.virtualenvs/mysites/lib/python3.6/site-packages/django/core/handlers/exception.py", line 90, in response_for_exception
    response = handle_uncaught_exception(request, get_resolver(get_urlconf()), sys.exc_info())
  File "/home/pyvip/.virtualenvs/mysites/lib/python3.6/site-packages/django/core/handlers/exception.py", line 128, in handle_uncaught_exception
    callback, param_dict = resolver.resolve_error_handler(500)
  File "/home/pyvip/.virtualenvs/mysites/lib/python3.6/site-packages/django/urls/resolvers.py", line 546, in resolve_error_handler
    callback = getattr(self.urlconf_module, 'handler%s' % view_type, None)
  File "/home/pyvip/.virtualenvs/mysites/lib/python3.6/site-packages/django/utils/functional.py", line 37, in __get__
    res = instance.__dict__[self.name] = self.func(instance)
  File "/home/pyvip/.virtualenvs/mysites/lib/python3.6/site-packages/django/urls/resolvers.py", line 526, in urlconf_module
    return import_module(self.urlconf_name)
  File "/home/pyvip/.virtualenvs/mysites/lib/python3.6/importlib/__init__.py", line 126, in import_module
    return _bootstrap._gcd_import(name[level:], package, level)
  File "<frozen importlib._bootstrap>", line 994, in _gcd_import
  File "<frozen importlib._bootstrap>", line 971, in _find_and_load
  File "<frozen importlib._bootstrap>", line 955, in _find_and_load_unlocked
  File "<frozen importlib._bootstrap>", line 665, in _load_unlocked
  File "<frozen importlib._bootstrap_external>", line 678, in exec_module
  File "<frozen importlib._bootstrap>", line 219, in _call_with_frames_removed
  File "./mysite/urls.py", line 23, in <module>
    path('', include('news.urls')),
  File "/home/pyvip/.virtualenvs/mysites/lib/python3.6/site-packages/django/urls/conf.py", line 34, in include
    urlconf_module = import_module(urlconf_module)
  File "/home/pyvip/.virtualenvs/mysites/lib/python3.6/importlib/__init__.py", line 126, in import_module
    return _bootstrap._gcd_import(name[level:], package, level)
  File "<frozen importlib._bootstrap>", line 994, in _gcd_import
  File "<frozen importlib._bootstrap>", line 971, in _find_and_load
  File "<frozen importlib._bootstrap>", line 955, in _find_and_load_unlocked
  File "<frozen importlib._bootstrap>", line 665, in _load_unlocked
  File "<frozen importlib._bootstrap_external>", line 678, in exec_module
  File "<frozen importlib._bootstrap>", line 219, in _call_with_frames_removed
  File "/home/pyvip/project/mysite/apps/news/urls.py", line 2, in <module>
    from news import views
  File "/home/pyvip/project/mysite/apps/news/views.py", line 31, in <module>
    @method_decorator(cache_page(timeout=120, cache='page_cache'), name='dispatch')
  File "/home/pyvip/.virtualenvs/mysites/lib/python3.6/site-packages/django/views/decorators/cache.py", line 23, in cache_page
    cache_timeout=timeout, cache_alias=cache, key_prefix=key_prefix
  File "/home/pyvip/.virtualenvs/mysites/lib/python3.6/site-packages/django/utils/decorators.py", line 128, in _make_decorator
    middleware = middleware_class(*m_args, **m_kwargs)
  File "/home/pyvip/.virtualenvs/mysites/lib/python3.6/site-packages/django/middleware/cache.py", line 189, in __init__
    self.cache = caches[self.cache_alias]
  File "/home/pyvip/.virtualenvs/mysites/lib/python3.6/site-packages/django/core/cache/__init__.py", line 76, in __getitem__
    "Could not find config for '%s' in settings.CACHES" % alias
django.core.cache.backends.base.InvalidCacheBackendError: Could not find config for 'page_cache' in settings.CACHES

During handling of the above exception, another exception occurred:

Traceback (most recent call last):
  File "/home/pyvip/.virtualenvs/mysites/lib/python3.6/site-packages/django/core/handlers/exception.py", line 34, in inner
    response = get_response(request)
  File "/home/pyvip/.virtualenvs/mysites/lib/python3.6/site-packages/django/utils/deprecation.py", line 91, in __call__
    response = response or self.get_response(request)
  File "/home/pyvip/.virtualenvs/mysites/lib/python3.6/site-packages/django/core/handlers/exception.py", line 36, in inner
    response = response_for_exception(request, exc)
  File "/home/pyvip/.virtualenvs/mysites/lib/python3.6/site-packages/django/core/handlers/exception.py", line 90, in response_for_exception
    response = handle_uncaught_exception(request, get_resolver(get_urlconf()), sys.exc_info())
  File "/home/pyvip/.virtualenvs/mysites/lib/python3.6/site-packages/django/core/handlers/exception.py", line 128, in handle_uncaught_exception
    callback, param_dict = resolver.resolve_error_handler(500)
  File "/home/pyvip/.virtualenvs/mysites/lib/python3.6/site-packages/django/urls/resolvers.py", line 546, in resolve_error_handler
    callback = getattr(self.urlconf_module, 'handler%s' % view_type, None)
  File "/home/pyvip/.virtualenvs/mysites/lib/python3.6/site-packages/django/utils/functional.py", line 37, in __get__
    res = instance.__dict__[self.name] = self.func(instance)
  File "/home/pyvip/.virtualenvs/mysites/lib/python3.6/site-packages/django/urls/resolvers.py", line 526, in urlconf_module
    return import_module(self.urlconf_name)
  File "/home/pyvip/.virtualenvs/mysites/lib/python3.6/importlib/__init__.py", line 126, in import_module
    return _bootstrap._gcd_import(name[level:], package, level)
  File "<frozen importlib._bootstrap>", line 994, in _gcd_import
  File "<frozen importlib._bootstrap>", line 971, in _find_and_load
  File "<frozen importlib._bootstrap>", line 955, in _find_and_load_unlocked
  File "<frozen importlib._bootstrap>", line 665, in _load_unlocked
  File "<frozen importlib._bootstrap_external>", line 678, in exec_module
  File "<frozen importlib._bootstrap>", line 219, in _call_with_frames_removed
  File "./mysite/urls.py", line 23, in <module>
    path('', include('news.urls')),
  File "/home/pyvip/.virtualenvs/mysites/lib/python3.6/site-packages/django/urls/conf.py", line 34, in include
    urlconf_module = import_module(urlconf_module)
  File "/home/pyvip/.virtualenvs/mysites/lib/python3.6/importlib/__init__.py", line 126, in import_module
    return _bootstrap._gcd_import(name[level:], package, level)
  File "<frozen importlib._bootstrap>", line 994, in _gcd_import
  File "<frozen importlib._bootstrap>", line 971, in _find_and_load
  File "<frozen importlib._bootstrap>", line 955, in _find_and_load_unlocked
  File "<frozen importlib._bootstrap>", line 665, in _load_unlocked
  File "<frozen importlib._bootstrap_external>", line 678, in exec_module
  File "<frozen importlib._bootstrap>", line 219, in _call_with_frames_removed
  File "/home/pyvip/project/mysite/apps/news/urls.py", line 2, in <module>
    from news import views
  File "/home/pyvip/project/mysite/apps/news/views.py", line 31, in <module>
    @method_decorator(cache_page(timeout=120, cache='page_cache'), name='dispatch')
  File "/home/pyvip/.virtualenvs/mysites/lib/python3.6/site-packages/django/views/decorators/cache.py", line 23, in cache_page
    cache_timeout=timeout, cache_alias=cache, key_prefix=key_prefix
  File "/home/pyvip/.virtualenvs/mysites/lib/python3.6/site-packages/django/utils/decorators.py", line 128, in _make_decorator
    middleware = middleware_class(*m_args, **m_kwargs)
  File "/home/pyvip/.virtualenvs/mysites/lib/python3.6/site-packages/django/middleware/cache.py", line 189, in __init__
    self.cache = caches[self.cache_alias]
  File "/home/pyvip/.virtualenvs/mysites/lib/python3.6/site-packages/django/core/cache/__init__.py", line 76, in __getitem__
    "Could not find config for '%s' in settings.CACHES" % alias
django.core.cache.backends.base.InvalidCacheBackendError: Could not find config for 'page_cache' in settings.CACHES

During handling of the above exception, another exception occurred:

Traceback (most recent call last):
  File "/home/pyvip/.virtualenvs/mysites/lib/python3.6/site-packages/django/core/handlers/wsgi.py", line 142, in __call__
    response = self.get_response(request)
  File "/home/pyvip/.virtualenvs/mysites/lib/python3.6/site-packages/django/core/handlers/base.py", line 78, in get_response
    response = self._middleware_chain(request)
  File "/home/pyvip/.virtualenvs/mysites/lib/python3.6/site-packages/django/core/handlers/exception.py", line 36, in inner
    response = response_for_exception(request, exc)
  File "/home/pyvip/.virtualenvs/mysites/lib/python3.6/site-packages/django/core/handlers/exception.py", line 90, in response_for_exception
    response = handle_uncaught_exception(request, get_resolver(get_urlconf()), sys.exc_info())
  File "/home/pyvip/.virtualenvs/mysites/lib/python3.6/site-packages/django/core/handlers/exception.py", line 128, in handle_uncaught_exception
    callback, param_dict = resolver.resolve_error_handler(500)
  File "/home/pyvip/.virtualenvs/mysites/lib/python3.6/site-packages/django/urls/resolvers.py", line 546, in resolve_error_handler
    callback = getattr(self.urlconf_module, 'handler%s' % view_type, None)
  File "/home/pyvip/.virtualenvs/mysites/lib/python3.6/site-packages/django/utils/functional.py", line 37, in __get__
    res = instance.__dict__[self.name] = self.func(instance)
  File "/home/pyvip/.virtualenvs/mysites/lib/python3.6/site-packages/django/urls/resolvers.py", line 526, in urlconf_module
    return import_module(self.urlconf_name)
  File "/home/pyvip/.virtualenvs/mysites/lib/python3.6/importlib/__init__.py", line 126, in import_module
    return _bootstrap._gcd_import(name[level:], package, level)
  File "<frozen importlib._bootstrap>", line 994, in _gcd_import
  File "<frozen importlib._bootstrap>", line 971, in _find_and_load
  File "<frozen importlib._bootstrap>", line 955, in _find_and_load_unlocked
  File "<frozen importlib._bootstrap>", line 665, in _load_unlocked
  File "<frozen importlib._bootstrap_external>", line 678, in exec_module
  File "<frozen importlib._bootstrap>", line 219, in _call_with_frames_removed
  File "./mysite/urls.py", line 23, in <module>
    path('', include('news.urls')),
  File "/home/pyvip/.virtualenvs/mysites/lib/python3.6/site-packages/django/urls/conf.py", line 34, in include
    urlconf_module = import_module(urlconf_module)
  File "/home/pyvip/.virtualenvs/mysites/lib/python3.6/importlib/__init__.py", line 126, in import_module
    return _bootstrap._gcd_import(name[level:], package, level)
  File "<frozen importlib._bootstrap>", line 994, in _gcd_import
  File "<frozen importlib._bootstrap>", line 971, in _find_and_load
  File "<frozen importlib._bootstrap>", line 955, in _find_and_load_unlocked
  File "<frozen importlib._bootstrap>", line 665, in _load_unlocked
  File "<frozen importlib._bootstrap_external>", line 678, in exec_module
  File "<frozen importlib._bootstrap>", line 219, in _call_with_frames_removed
  File "/home/pyvip/project/mysite/apps/news/urls.py", line 2, in <module>
    from news import views
  File "/home/pyvip/project/mysite/apps/news/views.py", line 31, in <module>
    @method_decorator(cache_page(timeout=120, cache='page_cache'), name='dispatch')
  File "/home/pyvip/.virtualenvs/mysites/lib/python3.6/site-packages/django/views/decorators/cache.py", line 23, in cache_page
    cache_timeout=timeout, cache_alias=cache, key_prefix=key_prefix
  File "/home/pyvip/.virtualenvs/mysites/lib/python3.6/site-packages/django/utils/decorators.py", line 128, in _make_decorator
    middleware = middleware_class(*m_args, **m_kwargs)
  File "/home/pyvip/.virtualenvs/mysites/lib/python3.6/site-packages/django/middleware/cache.py", line 189, in __init__
    self.cache = caches[self.cache_alias]
  File "/home/pyvip/.virtualenvs/mysites/lib/python3.6/site-packages/django/core/cache/__init__.py", line 76, in __getitem__
    "Could not find config for '%s' in settings.CACHES" % alias
django.core.cache.backends.base.InvalidCacheBackendError: Could not find config for 'page_cache' in settings.CACHES
[pid: 9078|app: 0|req: 1/1] 127.0.0.1 () {32 vars in 344 bytes} [Tue Jun  4 18:52:10 2019] HEAD / => generated 0 bytes in 2327 msecs (HTTP/1.1 500) 0 headers in 0 bytes (0 switches on core 0)
SIGINT/SIGQUIT received...killing workers...
worker 1 buried after 1 seconds
goodbye to uWSGI.
*** Starting uWSGI 2.0.18 (64bit) on [Tue Jun  4 19:21:00 2019] ***
compiled with version: 7.3.0 on 26 May 2019 07:39:13
os: Linux-4.15.0-36-generic #39-Ubuntu SMP Mon Sep 24 16:19:09 UTC 2018
nodename: VIP
machine: x86_64
clock source: unix
pcre jit disabled
detected number of CPU cores: 1
current working directory: /home/pyvip/project/mysite/deploy
writing pidfile to uwsgi.pid
detected binary path: /home/pyvip/.virtualenvs/mysites/bin/uwsgi
chdir() to /home/pyvip/project/mysite
your processes number limit is 3705
your memory page size is 4096 bytes
detected max file descriptor number: 1024
lock engine: pthread robust mutexes
thunder lock: disabled (you can enable it with --thunder-lock)
uwsgi socket 0 bound to TCP address 10.0.2.15:8000 fd 3
Python version: 3.6.6 (default, Sep 12 2018, 18:26:19)  [GCC 8.0.1 20180414 (experimental) [trunk revision 259383]]
Set PythonHome to /home/pyvip/.virtualenvs/mysites
Python main interpreter initialized at 0x5610ffd5ca60
python threads support enabled
your server socket listen backlog is limited to 100 connections
your mercy for graceful operations on workers is 60 seconds
mapped 145840 bytes (142 KB) for 1 cores
*** Operational MODE: single process ***
WSGI app 0 (mountpoint='') ready in 8 seconds on interpreter 0x5610ffd5ca60 pid: 9265 (default app)
*** uWSGI is running in multiple interpreter mode ***
spawned uWSGI master process (pid: 9265)
spawned uWSGI worker 1 (pid: 9267, cores: 1)
[pid: 9267|app: 0|req: 1/1] 127.0.0.1 () {32 vars in 344 bytes} [Tue Jun  4 19:21:39 2019] HEAD / => generated 8925 bytes in 9417 msecs (HTTP/1.1 200) 5 headers in 292 bytes (1 switches on core 0)
